Workbook
Name NativeTimeline_Date: #N/A
Name Slicer_Budget: #N/A
Name Slicer_Campaign: #N/A
Name Slicer_Hole_Type: #N/A

Sheet Dashboard
A1: Drilling to Date
A2: DD
B3: {=_xlfn.LET( _xlpm.cats, _xlfn.VSTACK( 'DDH1 RIG 38'!B5:B149, 'DDH1 RIG 38'!B5:B149, 'DDH1 RIG 41'!B5:B149, 'DDH1 RIG 41'!B5:B149 ), _xlpm.vals, _xlfn.VSTACK( 'DDH1 RIG 38'!F5:F149, 'DDH1 RIG 38'!G5:G149, 'DDH1 RIG 41'!F5:F149, 'DDH1 RIG 41'!G5:G149 ), _xlpm.mask, ISTEXT(_xlpm.vals), _xlpm.c, _xlfn._xlws.FILTER(_xlpm.cats, _xlpm.mask), _xlpm.v, _xlfn._xlws.FILTER(_xlpm.vals, _xlpm.mask), _xlpm.uC, _xlfn.UNIQUE(_xlpm.c), _xlfn.HSTACK( _xlpm.uC, _xlfn.MAP(_xlpm.uC, _xlfn.LAMBDA(_xlpm.x, COUNTA(_xlfn.UNIQUE(_xlfn._xlws.FILTER(_xlpm.v, _xlpm.c=_xlpm.x))))) ) )} -> Met | C3: 27
B4: Geotech | C4: 14
B5: A Vein DD | C5: 7
B6: Infill | C6: 5
B7: G Vein DD | C7: 4
A9: RC
B10: {=_xlfn.LET( _xlpm.cats, _xlfn.VSTACK('STR RIG 18'!B5:B149,'STR RIG 18'!B5:B149,'STR RIG 18'!B5:B149,'STR RIG 18'!B5:B149), _xlpm.vals, _xlfn.VSTACK('STR RIG 18'!E5:E149,'STR RIG 18'!F5:F149,'STR RIG 18'!G5:G149,'STR RIG 18'!H5:H149), _xlpm.mask, ISTEXT(_xlpm.vals), _xlpm.c, _xlfn._xlws.FILTER(_xlpm.cats,_xlpm.mask), _xlpm.v, _xlfn._xlws.FILTER(_xlpm.vals,_xlpm.mask), _xlpm.uC, _xlfn.UNIQUE(_xlpm.c), _xlfn.HSTACK( _xlpm.uC, _xlfn.MAP(_xlpm.uC,_xlfn.LAMBDA(_xlpm.x,COUNTA(_xlfn.UNIQUE(_xlfn._xlws.FILTER(_xlpm.v,_xlpm.c=_xlpm.x))))) ) )} -> A Vein RC | C10: 42
B11: Infill | C11: 38
B12: G Vein RC | C12: 38
D15: Actual | E15: Monthly
A16: S042 | B16: Drilling | C16: vendor | D16: 1223 | F16: Red

Sheet Pivot_Summary
A2: Rig 38
A3: Row Labels | B3: Sum of Total Costs
B4: 3780 | M4: Type | N4: Total Cost
A5: DDRD | B5: 48065.74 | M5: DDRD | N5: =GETPIVOTDATA("Total Costs",$A$3,"Hole Type","DDRD")+GETPIVOTDATA("Total Costs",$A$19,"Hole Type","DDRD") -> 117511.39
A6: GT | B6: 156449.69 | M6: GT | N6: =GETPIVOTDATA("Total Costs",$A$3,"Hole Type","GT")+GETPIVOTDATA("Total Costs",$A$19,"Hole Type","GT") -> 292723.41
A7: Index | B7: 37 | M7: MET | N7: =GETPIVOTDATA("Total Costs",$A$3,"Hole Type","MET")+GETPIVOTDATA("Total Costs",$A$19,"Hole Type","MET") -> 796476.73
A8: MET | B8: 256886.28 | M8: INF | N8: =GETPIVOTDATA("Total Costs",$A$32,"Hole Purpose","INF") -> 474557.5
A9: (blank) | B9: 0 | M9: EXT | N9: =GETPIVOTDATA("Total Costs",$A$32,"Hole Purpose","EXT") -> 208987.98
A10: Grand Total | B10: 465218.71
M11: Total | N11: =SUM(N5:N9) -> 1890257
A18: Rig 41
A19: Row Labels | B19: Sum of Total Costs
A20: DDRD | B20: 69445.65
A21: GT | B21: 136273.72
A22: Index | B22: 37
A23: MET | B23: 539590.45
A24: 45821.71 | B24: 0
A25: 45822.71 | B25: 0
A26: 45823.71 | B26: 0
A27: 45824.71 | B27: 0
A28: (blank) | B28: #VALUE!
A29: Grand Total | B29: #VALUE!
A31: Strike
A32: Row Labels | B32: Sum of Total Costs
A33: EXT | B33: 208987.98
A34: Index | B34: 28
A35: INF | B35: 474557.5
A36: (blank) | B36: 19201.02
A37: Grand Total | B37: 702774.5

Sheet Scheduler
E1: Schedule | H1: =TEXT(H2,"DDDD") -> Thursday | I1: =TEXT(I2,"DDDD") -> Friday | J1: =TEXT(J2,"DDDD") -> Saturday | K1: =TEXT(K2,"DDDD") -> Sunday | L1: =TEXT(L2,"DDDD") -> Monday | M1: =TEXT(M2,"DDDD") -> Tuesday | N1: =TEXT(N2,"DDDD") -> Wednesday | O1: =TEXT(O2,"DDDD") -> Thursday | ... FV1: =TEXT(FV2,"DDDD") -> Saturday
A2: Adequate? | B2: Planned | C2: Actual | E2: Activity Type | F2: Rig | G2: Notes | H2: 45785 | I2: 45786 | J2: 45787 | K2: 45788 | L2: 45789 | M2: 45790 | N2: 45791 | O2: 45792 | P2: 45793 | Q2: 45794 | R2: 45795 | S2: 45796 | T2: 45797 | U2: 45798 | V2: 45799 | W2: 45800 | X2: 45801 | Y2: 45802 | Z2: 45803 | AA2: 45804 | AB2: 45805 | AC2: 45806 | AD2: 45807 | AE2: 45808 | AF2: 45809 | AG2: 45810 | AH2: 45811 | AI2: 45812 | AJ2: 45813 | AK2: 45814 | AL2: 45815 | AM2: 45816 | AN2: 45817 | AO2: 45818 | AP2: 45819 | AQ2: 45820 | AR2: 45821 | AS2: 45822 | AT2: 45823 | AU2: 45824 | AV2: 45825 | AW2: 45826 | AX2: 45827 | AY2: 45828 | AZ2: 45829 | BA2: 45830 | BB2: 45831 | BC2: 45832 | BD2: 45833 | BE2: 45834 | BF2: 45835 | BG2: 45836 | BH2: 45837 | BI2: 45838 | BJ2: 45839 | BK2: 45840 | BL2: 45841 | BM2: 45842 | BN2: 45843 | BO2: 45844 | BP2: 45845 | BQ2: 45846 | BR2: 45847 | BS2: 45848 | BT2: 45849 | BU2: 45850 | BV2: 45851 | BW2: 45852 | BX2: 45853 | BY2: 45854 | BZ2: 45855 | CA2: 45856 | CB2: 45857 | CC2: 45858 | CD2: 45859 | CE2: 45860 | CF2: 45861 | CG2: 45862 | CH2: 45863 | CI2: 45864 | CJ2: 45865 | CK2: 45866 | CL2: 45867 | CM2: 45868 | CN2: 45869 | CO2: 45870 | CP2: 45871 | CQ2: 45872 | CR2: 45873 | CS2: 45874 | CT2: 45875 | CU2: 45876 | CV2: 45877 | CW2: 45878 | CX2: 45879 | CY2: 45880 | CZ2: 45881 | DA2: 45882 | DB2: 45883 | DC2: 45884 | DD2: 45885 | DE2: 45886 | DF2: 45887 | DG2: 45888 | DH2: 45889 | DI2: 45890 | DJ2: 45891 | DK2: 45892 | DL2: 45893 | DM2: 45894 | DN2: 45895 | DO2: 45896 | DP2: 45897 | DQ2: 45898 | DR2: 45899 | DS2: 45900 | DT2: 45901 | DU2: 45902 | DV2: 45903 | DW2: 45904 | DX2: 45905 | DY2: 45906 | DZ2: 45907 | EA2: 45908 | EB2: 45909 | EC2: 45910 | ED2: 45911 | EE2: 45912 | EF2: 45913 | EG2: 45914 | EH2: 45915 | EI2: 45916 | EJ2: 45917 | EK2: 45918 | EL2: 45919 | EM2: 45920 | EN2: 45921 | EO2: 45922 | EP2: 45923 | EQ2: 45924 | ER2: 45925 | ES2: 45926 | ET2: 45927 | EU2: 45928 | EV2: 45929 | EW2: 45930 | EX2: 45931 | EY2: 45932 | EZ2: 45933 | FA2: 45934 | FB2: 45935 | FC2: 45936 | FD2: 45937 | FE2: 45938 | FF2: 45939 | FG2: 45940 | FH2: 45941 | FI2: 45942 | FJ2: 45943 | FK2: 45944 | FL2: 45945 | FM2: 45946 | FN2: 45947 | FO2: 45948 | FP2: 45949 | FQ2: 45950 | FR2: 45951 | FS2: 45952 | FT2: 45953 | FU2: 45954 | FV2: 45955
A3: GENERAL EARTH WORKS | H3: Task 1 - ACCESS | O3: Task 2 - RingRoad | V3: Task 3 - Station Link | BO3: Task 5 - Test Pits | DM3: Task 7 - Rehab
G4: Survey | H4: Initial Survey | BK4: Collar Survey | CP4: Collar Survey | DY4: Collar Survey
E5: DDR1 | G5: Drilling Phase | AW5: Met | AX5: Met | AY5: Met | AZ5: Met | BA5: Met | BB5: Met | BC5: Met | BD5: Met | BE5: Met | BF5: Met | BG5: Met | BH5: Met | BI5: Met | BJ5: Met | BK5: Met | BL5: Met | BM5: Met | BN5: Met | BO5: Met | BP5: Met | BQ5: Met | BR5: Met | BS5: Met | BT5: Met | BU5: Met | BV5: Met | BW5: Met | BX5: Met | BY5: Met | BZ5: Met | CA5: Met | CB5: GeoT* | CC5: GeoT* | CD5: GeoT* | CE5: GeoT* | CF5: GeoT* | CG5: GeoT* | CH5: GeoT* | CI5: GeoT* | CJ5: GeoT* | CK5: Met | CL5: Met | CM5: Met | CN5: Met | CO5: Met | CP5: Met | CQ5: Met | CR5: Met | CS5: GT | CT5: GT | CU5: GT | CV5: GT | CW5: GT | CX5: DDRD | CY5: DDRD | CZ5: DDRD | DA5: Met | DB5: Met | DC5: Met | DD5: Met | DE5: Inf | DF5: Inf | DG5: Inf | DH5: Inf | DI5: ExtG | DJ5: ExtG | DK5: ExtG | DL5: ExtG | DM5: Inf | DN5: Inf | DO5: Inf | DP5: Inf | DQ5: Inf | DR5: Additonal Met | DS5: Additonal Met | DT5: Additonal Met | DU5: Additonal Met | DV5: Additonal Met | DW5: Additonal Met | DX5: Additonal Met | DY5: Additonal Met | DZ5: Additonal Met | EA5: Additonal Met | EB5: Additonal Met | EC5: Additonal Met | ED5: Additonal Met | EE5: Additonal Met | EF5: Additonal Met | EG5: Additonal Met | EH5: Additonal Met | EI5: Additonal Met | EJ5: Additonal Met | EK5: Additonal Met | EL5: Additonal Met | EM5: Additonal Met | EN5: Additonal Met | EO5: Additonal Met | EP5: Additonal Met | EQ5: Additonal Met | ER5: Additonal Met | ES5: Additonal Met | ET5: Additonal Met | EU5: Additonal Met | EV5: Additonal Met | EW5: Additonal Met | EX5: Additonal Met | EY5: Additonal Met | EZ5: Additonal Met | FA5: Additonal Met | FB5: Additonal Met | FC5: Additonal Met | FD5: Additonal Met | FE5: Additonal Met | FF5: Additonal Met | FG5: Additonal Met | FH5: Additonal Met | FI5: Additonal Met | FJ5: Additonal Met | FK5: Additonal Met | FL5: Additonal Met | FM5: Additonal Met | FN5: Additonal Met | FO5: Additonal Met | FP5: Additonal Met | FQ5: Additonal Met | FR5: Additonal Met
A6: =IF((C6+40)>=B6,TRUE,FALSE) -> TRUE | B6: 2045 | C6: =SUM(Y6:XFD6) -> 3260 | E6: Drilling | F6: DD PQ -> HQ | G6: Predicted | AW6: 25 | AX6: 25 | AY6: 25 | AZ6: 25 | BA6: 25 | BB6: 25 | BC6: 25 | BD6: 25 | BE6: 25 | BF6: 25 | BG6: 25 | BH6: 25 | BI6: 25 | BJ6: 25 | BK6: 25 | BL6: 25 | BM6: 25 | BN6: 25 | BO6: 25 | BP6: 25 | BQ6: 25 | BR6: 25 | BS6: 25 | BT6: 25 | BU6: 25 | BV6: 25 | BW6: 25 | BX6: 25 | BY6: 25 | BZ6: 25 | CA6: 25 | CB6: 30 | CC6: 30 | CD6: 30 | CE6: 30 | CF6: 30 | CG6: 30 | CH6: 30 | CI6: 30 | CJ6: 30 | CK6: 25 | CL6: 25 | CM6: 25 | CN6: 25 | CO6: 25 | CP6: 25 | CQ6: 25 | CR6: 25 | CS6: 30 | CT6: 30 | CU6: 30 | CV6: 30 | CW6: 30 | CX6: 30 | CY6: 30 | CZ6: 30 | DA6: 25 | DB6: 25 | DC6: 25 | DD6: 25 | DE6: 30 | DF6: 30 | DG6: 30 | DH6: 30 | DI6: 30 | DJ6: 30 | DK6: 30 | DL6: 30 | DM6: 30 | DN6: 30 | DO6: 30 | DP6: 30 | DQ6: 30 | DR6: 25 | DS6: 25 | DT6: 25 | DU6: 25 | DV6: 25 | DW6: 25 | DX6: 25 | DY6: 25 | DZ6: 25 | EA6: 25 | EB6: 25 | EC6: 15 | ED6: 15 | EE6: 15 | EF6: 15 | EG6: 25 | EH6: 25 | EI6: 25 | EJ6: 25 | EK6: 25 | EL6: 25 | EM6: 25 | EN6: 25 | EO6: 25 | EP6: 25 | EQ6: 25 | ER6: 25 | ES6: 25 | ET6: 25 | EU6: 25 | EV6: 25 | EW6: 25 | EX6: 25 | EY6: 25 | EZ6: 25 | FA6: 25 | FB6: 25 | FC6: 25 | FD6: 25 | FE6: 25 | FF6: 25 | FG6: 25 | FH6: 25 | FI6: 25 | FJ6: 25 | FK6: 25 | FL6: 25 | FM6: 25 | FN6: 25 | FO6: 25 | FP6: 25 | FQ6: 25 | FR6: 25
E7: DR41 | G7: Actual | AV7: 0 | AW7: 51.5 | AX7: 56 | AY7: 52.5 | AZ7: 21.4 | BA7: 58.6 | BB7: 30 | BC7: 32.6 | BD7: 23 | BE7: 65.1 | BF7: 43.9 | BG7: 36.1 | BH7: 45.4 | BI7: 21 | BJ7: 20.6 | BK7: 34.4 | BL7: 15.8 | BM7: 30.4 | BN7: 38.5 | BO7: =17.9+8.3 -> 26.2 | BP7: =10.4+26.4 -> 36.8 | BQ7: =5.6+27 -> 32.6 | BR7: =9.6+11.4 -> 21 | BS7: =7.9+19.6 -> 27.5 | BT7: =18+10.2 -> 28.2 | BU7: =10.8+21 -> 31.8 | BV7: =3+14.5 -> 17.5 | BW7: =12.7+24 -> 36.7 | BX7: =10.3+13.8 -> 24.1 | BY7: 33 | BZ7: =20.7+11.5 -> 32.2 | CA7: =21.8+12 -> 33.8 | CB7: =30.6+30 -> 60.6 | CC7: =30+19.4 -> 49.4 | CD7: =30.6+30 -> 60.6 | CE7: =30+19.4 -> 49.4 | CF7: =11.9+30.5 -> 42.4 | CG7: 60 | CH7: =17.6+18.5 -> 36.1 | CI7: =60 -> 60 | CJ7: =30+21.5 -> 51.5 | CK7: 39.2 | CL7: 16.6 | CM7: 22.4 | CN7: 43.9 | CO7: 48.4 | CP7: 24.6 | CQ7: 49.7 | CR7: 29.8 | CS7: 24.3 | CT7: 63.7 | CU7: 28.7 | CV7: 64.8 | CW7: 45.7 | CX7: 59.3 | CY7: 44.9 | CZ7: 44.1 | DA7: 7.2 | DB7: 44.4 | DC7: 30 | DD7: 30.8 | DE7: 66.4 | DF7: 66 | DG7: 69 | DH7: 33 | DI7: 57.5 | DJ7: 16.5 | DK7: 72.7 | DL7: 46.8 | DM7: 68 | DN7: 51 | DO7: 30 | DP7: 35.9 | DQ7: 72.7 | DR7: 21.4 | DS7: 42 | DT7: =SUM(DT6:DU6) -> 50 | DU7: =SUM(DU6:DV6) -> 50 | DV7: =SUM(DV6:DW6) -> 50 | DW7: =SUM(DW6:DX6) -> 50 | DX7: =SUM(DX6:DY6) -> 50 | DY7: =SUM(DY6:DZ6) -> 50 | DZ7: =SUM(DZ6:EA6) -> 50 | EA7: 30.4 | EB7: 32.5 | EC7: 0.5 | ED7: 33 | EE7: 13.6 | EF7: 30.6 | EG7: 27.7 | EH7: 26.7 | EI7: 15.5 | EJ7: 30 | EK7: 22.2 | EL7: 28.8 | EM7: 23.5 | EN7: 12.6 | EO7: 29.7 | EP7: 24.3 | EQ7: 24 | ER7: 29.4 | ES7: 5.9 | ET7: 12.6 | EU7: 27 | EV7: 48 | EW7: 48.4 | EX7: 31.2 | EY7: 37 | EZ7: 32.7 | FA7: 27.2 | FB7: 6.8 | FC7: 10.9 | FD7: 12 | FE7: 4.7 | FF7: 39 | FG7: 8.9 | FH7: 27 | FI7: 21 | FJ7: 21 | FK7: 22.7 | FL7: 30.1 | FM7: 0 | FN7: 46.1 | FO7: 37 | FP7: 29.7
G8: Difference | AV8: =IF(ISBLANK(AV7),"",AV7-AV6) -> 0 | AW8: =IF(ISBLANK(AW7),"",AW7-AW6) -> 26.5 | AX8: =IF(ISBLANK(AX7),"",AX7-AX6) -> 31 | AY8: =IF(ISBLANK(AY7),"",AY7-AY6) -> 27.5 | AZ8: =IF(ISBLANK(AZ7),"",AZ7-AZ6) -> -3.6 | BA8: =IF(ISBLANK(BA7),"",BA7-BA6) -> 33.6 | BB8: =IF(ISBLANK(BB7),"",BB7-BB6) -> 5 | BC8: =IF(ISBLANK(BC7),"",BC7-BC6) -> 7.6 | ... FR8: =IF(ISBLANK(FR7),"",FR7-FR6)
G9: Cumulative Difference | AV9: =IFERROR(IF(ISBLANK(AV8),"",AV8+AU9),"") -> 0 | AW9: =IFERROR(IF(ISBLANK(AW8),"",AW8+AV9),"") -> 26.5 | AX9: =IFERROR(IF(ISBLANK(AX8),"",AX8+AW9),"") -> 57.5 | AY9: =IFERROR(IF(ISBLANK(AY8),"",AY8+AX9),"") -> 85 | AZ9: =IFERROR(IF(ISBLANK(AZ8),"",AZ8+AY9),"") -> 81.4 | BA9: =IFERROR(IF(ISBLANK(BA8),"",BA8+AZ9),"") -> 115 | BB9: =IFERROR(IF(ISBLANK(BB8),"",BB8+BA9),"") -> 120 | BC9: =IFERROR(IF(ISBLANK(BC8),"",BC8+BB9),"") -> 127.6 | ... FR9: =IFERROR(IF(ISBLANK(FR8),"",FR8+FQ9),"")
G10: 7 Day rolling average | BB10: =IFERROR(AVERAGE(AV7:BB7),"") -> 38.571429 | BI10: =IFERROR(AVERAGE(BC7:BI7),"") -> 38.157143 | BP10: =IFERROR(AVERAGE(BJ7:BP7),"") -> 28.957143 | BW10: =IFERROR(AVERAGE(BQ7:BW7),"") -> 27.9 | CD10: =IFERROR(AVERAGE(BX7:CD7),"") -> 41.957143 | CK10: =IFERROR(AVERAGE(CE7:CK7),"") -> 48.371429 | CR10: =IFERROR(AVERAGE(CL7:CR7),"") -> 33.628571 | CY10: =IFERROR(AVERAGE(CS7:CY7),"") -> 47.342857 | DF10: =IFERROR(AVERAGE(CZ7:DF7),"") -> 41.271429 | DM10: =IFERROR(AVERAGE(DF7:DL7),"") -> 51.642857 | DT10: =IFERROR(AVERAGE(DN7:DT7),"") -> 43.285714 | EA10: =IFERROR(AVERAGE(DU7:EA7),"") -> 47.2 | EH10: =IFERROR(AVERAGE(EB7:EH7),"") -> 23.514286 | EO10: =IFERROR(AVERAGE(EI7:EO7),"") -> 23.185714 | EV10: =IFERROR(AVERAGE(EP7:EV7),"") -> 24.457143 | FC10: =IFERROR(AVERAGE(EW7:FC7),"") -> 27.742857 | FJ10: =IFERROR(AVERAGE(FD7:FJ7),"") -> 19.085714 | FQ10: =IFERROR(AVERAGE(FK7:FQ7),"") -> 27.6
A11: Enabling Earthwork's Task | Y11: Task 4.1 - Prelim Pad Prep | Z11: Task 4.1 - Prelim Pad Prep | AA11: Task 4.1 - Prelim Pad Prep | AK11: Task 4.1 - Prelim Pad Prep | AL11: Task 4.1 - Prelim Pad Prep | AM11: Task 4.1 - Prelim Pad Prep
A12: =IF((C12+2.5)>=B12,TRUE,FALSE) -> TRUE | B12: 13 | C12: =SUM(Y12:XFD12) -> 15 | E12: Earthworks | Y12: 2.5 | Z12: 2.5 | AA12: 2.5 | AK12: 2.5 | AL12: 2.5 | AM12: 2.5 | FB12: task 7 | FC12: task 7 | FD12: task 7 | FE12: task 7 | FF12: task 7 | FG12: task 7 | FH12: task 7 | FI12: task 7 | FJ12: task 7 | FK12: task 7 | FL12: task 7 | FM12: task 7 | FN12: task 7 | FO12: task 7 | FP12: task 7 | FQ12: task 7 | FR12: task 7 | FS12: task 7 | FT12: task 7 | FU12: task 7 | FV12: task 7
E13: DDR2 | G13: Drilling Phase | BQ13: Met | BR13: Met | BS13: Met | BT13: Met | BU13: Met | BV13: Met | BW13: Met | BX13: Met | BY13: Met | BZ13: Met | CA13: Met | CB13: Met | CC13: GeoT * | CD13: GeoT * | CE13: GeoT * | CF13: Met | CG13: Met | CH13: GeoT * | CI13: GeoT * | CJ13: GeoT * | CK13: GeoT * | CL13: GeoT * | CM13: GeoT * | CN13: GeoT * | CO13: Met | CP13: Met | CQ13: Met | CR13: Met | CS13: Met | CT13: Met | CU13: Met | CV13: ExtA | CW13: ExtA | CX13: ExtA | CY13: GT | CZ13: ExtA | DA13: ExtA | DB13: ExtA | DC13: ExtA | DD13: Inf | DE13: Inf | DF13: ExtG | DG13: ExtG | DH13: ExtG | DI13: Inf | DJ13: Inf | DK13: Inf | DL13: Inf | DM13: Inf | DN13: Inf | DO13: Inf | DP13: Inf | DQ13: Inf | DR13: Inf | DS13: Inf | DT13: Inf | DU13: Inf | DV13: Inf | DW13: Inf | DX13: Inf | DY13: Inf | DZ13: Inf | EA13: Inf | EB13: ExtA | EC13: ExtA | ED13: ExtA | EE13: ExtA | EF13: ExtA | EG13: ExtA | EH13: ExtA | EI13: ExtA | EJ13: ExtA | EK13: ExtA | EL13: ExtA | EM13: ExtG | EN13: ExtG | EO13: ExtG | EP13: ExtG | EQ13: ExtG | ER13: ExtG | ES13: ExtG | ET13: ExtG | EU13: ExtG | EV13: ExtG | EW13: ExtG
A14: =IF((C14+40)>=B14,TRUE,FALSE) -> FALSE | B14: 3421 | C14: =SUM(Y14:XFD14) -> 3135 | E14: Drilling | F14: DD HQ | G14: Predicted | BQ14: 25 | BR14: 25 | BS14: 25 | BT14: 25 | BU14: 25 | BV14: 25 | BW14: 25 | BX14: 25 | BY14: 25 | BZ14: 25 | CA14: 25 | CB14: 25 | CC14: 30 | CD14: 30 | CE14: 30 | CF14: 25 | CG14: 25 | CH14: 30 | CI14: 30 | CJ14: 30 | CK14: 30 | CL14: 30 | CM14: 30 | CN14: 30 | CO14: 25 | CP14: 25 | CQ14: 25 | CR14: 25 | CS14: 25 | CT14: 25 | CU14: 25 | CV14: 30 | CW14: 30 | CX14: 30 | CY14: 30 | CZ14: 30 | DA14: 30 | DB14: 30 | DC14: 30 | DD14: 30 | DE14: 30 | DF14: 30 | DG14: 30 | DH14: 30 | DI14: 30 | DJ14: 30 | DK14: 30 | DL14: 30 | DM14: 30 | DN14: 30 | DO14: 30 | DP14: 30 | DQ14: 30 | DR14: 30 | DS14: 30 | DT14: 30 | DU14: 30 | DV14: 30 | DW14: 30 | DX14: 30 | DY14: 30 | DZ14: 30 | EA14: 30 | EB14: 30 | EC14: 30 | ED14: 30 | EE14: 30 | EF14: 30 | EG14: 30 | EH14: 30 | EI14: 30 | EJ14: 30 | EK14: 30 | EL14: 30 | EM14: 30 | EN14: 30 | EO14: 30 | EP14: 30 | EQ14: 30 | ER14: 30 | ES14: 30 | ET14: 30 | EU14: 30 | EV14: 30 | EW14: 30 | EX14: 30 | EY14: 30 | EZ14: 30 | FA14: 30 | FB14: 30 | FC14: 30 | FD14: 30 | FE14: 30 | FF14: 30 | FG14: 30 | FH14: 30 | FI14: 30 | FJ14: 30 | FK14: 30 | FL14: 30 | FM14: 30 | FN14: 30 | FO14: 30 | FP14: 30 | FQ14: 30 | FR14: 30 | FS14: 30 | FT14: 30
E15: DR38 | G15: Actual | BQ15: =11+15.6 -> 26.6 | BR15: =7.1+30 -> 37.1 | BS15: =20.4+15.6 -> 36 | BT15: =19+16.5 -> 35.5 | BU15: =22.9+21.2 -> 44.1 | BV15: =13.2+27.3 -> 40.5 | BW15: =19.6+20.5 -> 40.1 | BX15: 60.1 | BY15: =19+21.8 -> 40.8 | BZ15: =26.2+27.7 -> 53.9 | CA15: =6+14.9 -> 20.9 | CB15: 60.7 | CC15: =8.3+17.5 -> 25.8 | CD15: =21.5+21.9 -> 43.4 | CE15: =11+16.4 -> 27.4 | CF15: =7.6+27.4 -> 35 | CG15: =29.6+16.4 -> 46 | CH15: 7.8 | CI15: 14.2 | CJ15: 21.3 | CK15: 57.4 | CL15: 29 | CM15: 24 | CN15: 20.2 | CO15: 34.5 | CP15: 45.7 | CQ15: 60 | CR15: 22.1 | CS15: 38 | CT15: 34 | CU15: 10.7 | CV15: 23 | CW15: 62.6 | CX15: 27.7 | CY15: 72 | CZ15: 22.7 | DA15: 57.2 | DB15: 46 | DC15: 59.6 | DD15: 24.5 | DE15: 71.6 | DF15: 37 | DG15: 60.5 | DH15: 48.6 | DI15: 40.6 | DJ15: 64.5 | DK15: 63.5 | DL15: 62.2 | DM15: 30.9 | DN15: 71.9 | DO15: 62.4 | DP15: 39.8 | DQ15: 66 | DR15: 22.3 | DS15: DEMOB
G16: Difference | BQ16: =IF(ISBLANK(BQ15),"",BQ15-BQ14) -> 1.6 | BR16: =IF(ISBLANK(BR15),"",BR15-CN14) -> 7.1 | BS16: =IF(ISBLANK(BS15),"",BS15-CO14) -> 11 | BT16: =IF(ISBLANK(BT15),"",BT15-CP14) -> 10.5 | BU16: =IF(ISBLANK(BU15),"",BU15-CQ14) -> 19.1 | BV16: =IF(ISBLANK(BV15),"",BV15-CS14) -> 15.5 | BW16: =IF(ISBLANK(BW15),"",BW15-CT14) -> 15.1 | BX16: =IF(ISBLANK(BX15),"",BX15-CU14) -> 35.1 | BY16: =IF(ISBLANK(BY15),"",BY15-CV14) -> 10.8 | BZ16: =IF(ISBLANK(BZ15),"",BZ15-CW14) -> 23.9 | CA16: =IF(ISBLANK(CA15),"",CA15-CX14) -> -9.1 | CB16: =IF(ISBLANK(CB15),"",CB15-CY14) -> 30.7 | CC16: =IF(ISBLANK(CC15),"",CC15-CZ14) -> -4.2 | ... EW16: =IF(ISBLANK(EW15),"",EW15-FT14)
G17: Cumulative Difference | BQ17: =IFERROR(IF(ISBLANK(BQ16),"",BQ16+BP17),"") -> 1.6 | BR17: =IFERROR(IF(ISBLANK(BR16),"",BR16+BQ17),"") -> 8.7 | BS17: =IFERROR(IF(ISBLANK(BS16),"",BS16+BR17),"") -> 19.7 | BT17: =IFERROR(IF(ISBLANK(BT16),"",BT16+BS17),"") -> 30.2 | BU17: =IFERROR(IF(ISBLANK(BU16),"",BU16+BT17),"") -> 49.3 | BV17: =IFERROR(IF(ISBLANK(BV16),"",BV16+BU17),"") -> 64.8 | BW17: =IFERROR(IF(ISBLANK(BW16),"",BW16+BV17),"") -> 79.9 | BX17: =IFERROR(IF(ISBLANK(BX16),"",BX16+BW17),"") -> 115 | ... EW17: =IFERROR(IF(ISBLANK(EW16),"",EW16+EV17),"")
BW18: =IFERROR(AVERAGE(BQ15:BW15),"") -> 37.128571 | CD18: =IFERROR(AVERAGE(BX15:CD15),"") -> 43.657143 | CK18: =IFERROR(AVERAGE(CE15:CK15),"") -> 29.871429
A19: Enabling Earthwork's Task | AA19: Task 4.1 - Prelim Pad Prep | AB19: Task 4.1 - Prelim Pad Prep | AC19: Task 4.1 - Prelim Pad Prep | AN19: Task 4.2 - Complete Pad Prep | AO19: Task 4.2 - Complete Pad Prep
A20: =IF((C20+2.5)>=B20,TRUE,FALSE) -> TRUE | B20: 29 | C20: =SUM(Y20:XFD20) -> 33 | E20: Earthworks | AA20: 2.5 | AB20: 2.5 | AC20: 2.5 | AN20: 8.5 | AO20: 8.5 | BP20: 8.5
E21: RCD1 | G21: Drilling Phase | BC21: ExtA | BD21: ExtA | BE21: ExtA | BF21: ExtA | BG21: ExtA | BH21: ExtA | BI21: ExtA | BJ21: ExtA | BK21: ExtA | BL21: ExtA | BM21: ExtA | BN21: ExtA | BO21: ExtA | BP21: ExtA | BQ21: ExtA | BR21: ExtA | BS21: ExtG | BT21: ExtG | BU21: ExtG | BV21: ExtG | BW21: ExtG | BX21: ExtG | BY21: ExtG | BZ21: ExtG | CA21: ExtG | CB21: ExtG | CC21: ExtG | CD21: ExtG | CE21: ExtG | CF21: ExtG | CG21: ExtG | CH21: ExtG | CI21: ExtG | CJ21: Inf | CK21: Inf | CL21: Inf | CM21: Inf | CN21: Inf | CO21: Inf | CP21: Inf | CQ21: Inf | CR21: Inf | CS21: Inf | CT21: Inf | CU21: Inf | CV21: Inf | CW21: Inf | CX21: Inf | CY21: Inf | CZ21: Inf | DA21: Inf | DB21: Inf | DC21: Inf | DD21: Inf | DE21: Inf | DF21: Inf | DG21: Inf | DH21: Inf | DI21: Inf | DJ21: Inf | DK21: Inf | DL21: Inf | DM21: Inf | DN21: Inf | DO21: Inf | DP21: Inf | DQ21: Inf | DR21: Inf | DS21: Inf | DT21: Inf | DU21: Inf | DV21: Inf | DW21: Inf | DX21: Inf | DY21: Inf | DZ21: Inf | EA21: Inf | EB21: Inf | EC21: Inf | ED21: Inf | EE21: Inf | EF21: Inf | EG21: Inf | EH21: Inf | EI21: Inf | EJ21: Inf | EK21: Inf | EL21: Inf | EM21: Inf | EN21: Inf | EO21: Dingo | EP21: Dingo | EQ21: Dingo | ER21: Dingo | ES21: Dingo
A22: =IF((C22+200)>=B22,TRUE,FALSE) -> #REF! | B22: =(29549.1-#REF!)/2 -> #REF! | C22: =SUM(Y22:XFD22) -> 14250 | E22: Drilling | F22: RC 1 | G22: Predicted | BC22: 150 | BD22: 150 | BE22: 150 | BF22: 150 | BG22: 150 | BH22: 150 | BI22: 150 | BJ22: 150 | BK22: 150 | BL22: 150 | BM22: 150 | BN22: 150 | BO22: 150 | BP22: 150 | BQ22: 150 | BR22: 150 | BS22: 150 | BT22: 150 | BU22: 150 | BV22: 150 | BW22: 150 | BX22: 150 | BY22: 150 | BZ22: 150 | CA22: 150 | CB22: 150 | CC22: 150 | CD22: 150 | CE22: 150 | CF22: 150 | CG22: 150 | CH22: 150 | CI22: 150 | CJ22: 150 | CK22: 150 | CL22: 150 | CM22: 150 | CN22: 150 | CO22: 150 | CP22: 150 | CQ22: 150 | CR22: 150 | CS22: 150 | CT22: 150 | CU22: 150 | CV22: 150 | CW22: 150 | CX22: 150 | CY22: 150 | CZ22: 150 | DA22: 150 | DB22: 150 | DC22: 150 | DD22: 150 | DE22: 150 | DF22: 150 | DG22: 150 | DH22: 150 | DI22: 150 | DJ22: 150 | DK22: 150 | DL22: 150 | DM22: 150 | DN22: 150 | DO22: 150 | DP22: 150 | DQ22: 150 | DR22: 150 | DS22: 150 | DT22: 150 | DU22: 150 | DV22: 150 | DW22: 150 | DX22: 150 | DY22: 150 | DZ22: 150 | EA22: 150 | EB22: 150 | EC22: 150 | ED22: 150 | EE22: 150 | EF22: 150 | EG22: 150 | EH22: 150 | EI22: 150 | EJ22: 150 | EK22: 150 | EL22: 150 | EM22: 150 | EN22: 150 | EO22: 150 | EP22: 150 | EQ22: 150 | ER22: 150 | ES22: 150
G23: Actual | BC23: 46 | BD23: 100 | BE23: 160 | BF23: 206 | BG23: 188 | BH23: 212 | BI23: 181 | BJ23: 148 | BK23: 187 | BL23: 200 | BM23: 72 | BN23: 118 | BO23: 242 | BP23: 190 | BQ23: 0 | BR23: 0 | BS23: 0 | BT23: 152 | BU23: 146 | BV23: 154 | BW23: 140 | BX23: 124 | BY23: 46 | BZ23: 150 | CA23: 200 | CB23: 216 | CC23: 284 | CD23: 212 | CE23: 202 | CF23: 176 | CG23: 0 | CH23: 0 | CI23: 194 | CJ23: 242 | CK23: 220 | CL23: 136 | CM23: 46 | CN23: 190 | CO23: 214 | CP23: 184 | CQ23: 96 | CR23: 194 | CS23: 180 | CT23: 202 | CU23: 52 | CV23: 226 | CW23: 242 | CX23: 300 | CY23: 224 | CZ23: 302 | DA23: 260 | DB23: 252 | DC23: 258 | DD23: 252 | DE23: 260 | DF23: 254 | DG23: 302 | DH23: 308 | DI23: 256 | DJ23: 280 | DK23: 210 | DL23: 258 | DM23: 220 | DN23: 300 | DO23: 302 | DP23: 238 | DQ23: 250 | DR23: 236 | DS23: 202 | DT23: 218 | DU23: 214 | DV23: 206 | DW23: 102 | DX23: 176 | DY23: 224 | DZ23: 160 | EA23: DEMOB
G24: Difference | BC24: =IF(ISBLANK(BC23),"",BC23-BC22) -> -104 | BD24: =IF(ISBLANK(BD23),"",BD23-BD22) -> -50 | BE24: =IF(ISBLANK(BE23),"",BE23-BE22) -> 10 | BF24: =IF(ISBLANK(BF23),"",BF23-BF22) -> 56 | BG24: =IF(ISBLANK(BG23),"",BG23-BG22) -> 38 | BH24: =IF(ISBLANK(BH23),"",BH23-BH22) -> 62 | BI24: =IF(ISBLANK(BI23),"",BI23-BI22) -> 31 | BJ24: =IF(ISBLANK(BJ23),"",BJ23-BJ22) -> -2 | ... ES24: =IF(ISBLANK(ES23),"",ES23-ES22)
G25: Cumulative Difference | BC25: =IFERROR(IF(ISBLANK(BC24),"",BC24+BB25),"") -> -104 | BD25: =IFERROR(IF(ISBLANK(BD24),"",BD24+BC25),"") -> -154 | BE25: =IFERROR(IF(ISBLANK(BE24),"",BE24+BD25),"") -> -144 | BF25: =IFERROR(IF(ISBLANK(BF24),"",BF24+BE25),"") -> -88 | BG25: =IFERROR(IF(ISBLANK(BG24),"",BG24+BF25),"") -> -50 | BH25: =IFERROR(IF(ISBLANK(BH24),"",BH24+BG25),"") -> 12 | BI25: =IFERROR(IF(ISBLANK(BI24),"",BI24+BH25),"") -> 43 | BJ25: =IFERROR(IF(ISBLANK(BJ24),"",BJ24+BI25),"") -> 41 | ... ES25: =IFERROR(IF(ISBLANK(ES24),"",ES24+ER25),"")
G26: 7 Day rolling average | BH26: =IFERROR(AVERAGE(BB23:BH23),"") -> 152 | BO26: =IFERROR(AVERAGE(BI23:BO23),"") -> 164 | BV26: =IFERROR(AVERAGE(BP23:BV23),"") -> 91.714286 | CC26: =IFERROR(AVERAGE(BW23:CC23),"") -> 165.71429 | CJ26: =IFERROR(AVERAGE(CD23:CJ23),"") -> 146.57143 | CQ26: =IFERROR(AVERAGE(CK23:CQ23),"") -> 155.14286 | CR26: =IFERROR(AVERAGE(CL23:CR23),"") -> 151.42857 | CY26: =IFERROR(AVERAGE(CS23:CY23),"") -> 203.71429 | DF26: =IFERROR(AVERAGE(CZ23:DF23),"") -> 262.57143 | DM26: =IFERROR(AVERAGE(DG23:DM23),"") -> 262 | DT26: =IFERROR(AVERAGE(DN23:DT23),"") -> 249.42857 | EA26: =IFERROR(AVERAGE(DU23:EA23),"") -> 180.33333 | EH26: =IFERROR(AVERAGE(EB23:EH23),"") | EO26: =IFERROR(AVERAGE(EI23:EO23),"") | EV26: =IFERROR(AVERAGE(EP23:EV23),"")
A27: Enabling Earthwork's Task | AC27: Task 4.1 - Prelim Pad Prep | AD27: Task 4.1 - Prelim Pad Prep | AE27: Task 4.1 - Prelim Pad Prep | AG27: Task 4.1 - Prelim Pad Prep | AH27: Task 4.1 - Prelim Pad Prep | AI27: Task 4.1 - Prelim Pad Prep | AJ27: Task 4.1 - Prelim Pad Prep | AK27: Task 4.1 - Prelim Pad Prep | AP27: Task 4.2 - Complete Pad Prep | AQ27: Task 4.2 - Complete Pad Prep | AR27: Task 4.2 - Complete Pad Prep | AS27: Task 4.2 - Complete Pad Prep | AT27: Task 4.2 - Complete Pad Prep | AU27: Task 4.2 - Complete Pad Prep | AV27: Task 4.2 - Complete Pad Prep | BF27: Task 4.2 - Complete Pad Prep | BG27: Task 4.2 - Complete Pad Prep | BH27: Task 4.2 - Complete Pad Prep | BI27: Task 4.2 - Complete Pad Prep | BJ27: Task 4.2 - Complete Pad Prep
A28: =IF((C28+2.5)>=B28,TRUE,FALSE) -> TRUE | B28: 116.5 | C28: =SUM(Y28:XFD28) -> 123 | E28: Earthworks | AC28: 2.5 | AD28: 2.5 | AE28: 2.5 | AG28: 2.5 | AH28: 2.5 | AI28: 2.5 | AJ28: 2.5 | AK28: 2.5 | AP28: 8.5 | AQ28: 8.5 | AR28: 8.5 | AS28: 8.5 | AT28: 8.5 | AU28: 8.5 | AV28: 8.5 | BF28: 8.5 | BG28: 8.5 | BH28: 8.5 | BI28: 8.5 | BJ28: 9.5
E29: RCD2 | G29: Drilling Phase | BI29: ExtA | BJ29: ExtA | BK29: ExtA | BL29: ExtA | BM29: ExtA | BN29: ExtA | BO29: ExtA | BP29: ExtA | BQ29: ExtA | BR29: ExtG | BS29: ExtG | BT29: ExtG | BU29: ExtG | BV29: ExtG | BW29: ExtG | BX29: ExtG | BY29: ExtG | BZ29: ExtG | CA29: ExtG | CB29: ExtG | CC29: ExtG | CD29: ExtG | CE29: ExtG | CF29: ExtG | CG29: ExtG | CH29: Inf | CI29: Inf | CJ29: Inf | CK29: Inf | CL29: Inf | CM29: Inf | CN29: Inf | CO29: Inf | CP29: Inf | CQ29: Inf | CR29: Inf | CS29: Inf | CT29: Inf | CU29: Inf | CV29: Inf | CW29: Inf | CX29: Inf | CY29: Inf | CZ29: Inf | DA29: Inf | DB29: Inf | DC29: Inf | DD29: Inf | DE29: Inf | DF29: Inf | DG29: Inf | DH29: Inf | DI29: Inf | DJ29: Inf | DK29: Inf | DL29: Inf | DM29: Inf | DN29: Inf | DO29: Inf | DP29: Inf | DQ29: Inf | DR29: Inf | DS29: Inf | DT29: Inf | DU29: Inf | DV29: Inf | DW29: Inf | DX29: Inf | DY29: Inf | DZ29: Inf | EA29: Inf | EB29: Inf | EC29: Inf | ED29: Inf | EE29: Inf | EF29: Inf | EG29: Inf | EH29: Inf | EI29: Inf | EJ29: Inf | EK29: Inf | EL29: Inf | EM29: Inf | EN29: Inf | EO29: Inf | EP29: Inf | EQ29: Inf | ER29: South | ES29: South | ET29: South | EU29: South
A30: =IF((C30+200)>=B30,TRUE,FALSE) -> #REF! | B30: =(29549.1-#REF!)/2 -> #REF! | C30: =SUM(Y30:XFD30) -> 13850 | E30: Drilling | F30: RC 2 | G30: Predicted | BI30: 150 | BJ30: 150 | BK30: 150 | BL30: 150 | BM30: 150 | BN30: 150 | BO30: 150 | BP30: 150 | BQ30: 150 | BR30: 150 | BS30: 150 | BT30: 150 | BU30: 150 | BV30: 150 | BW30: 150 | BX30: 150 | BY30: 150 | BZ30: 150 | CA30: 150 | CB30: 150 | CC30: 150 | CD30: 150 | CE30: 150 | CF30: 150 | CG30: 150 | CH30: 150 | CI30: 150 | CJ30: 150 | CK30: 150 | CL30: 150 | CM30: 150 | CN30: 150 | CO30: 150 | CP30: 150 | CQ30: 150 | CR30: 150 | CS30: 150 | CT30: 150 | CU30: 150 | CV30: 150 | CW30: 150 | CX30: 150 | CY30: 150 | CZ30: 150 | DA30: 150 | DB30: 150 | DC30: 150 | DD30: 150 | DE30: 150 | DF30: 150 | DG30: 150 | DH30: 150 | DI30: 150 | DJ30: 150 | DK30: 150 | DL30: 150 | DM30: 150 | DN30: 150 | DO30: 150 | DP30: 150 | DQ30: 150 | DR30: 150 | DS30: 150 | DT30: 150 | DU30: 150 | DV30: 150 | DW30: 150 | DX30: 150 | DY30: 150 | DZ30: 150 | EA30: 150 | EB30: 150 | EC30: 150 | ED30: 150 | EE30: 150 | EF30: 150 | EG30: 150 | EH30: 150 | EI30: 150 | EJ30: 150 | EK30: 150 | EL30: 150 | EM30: 150 | EN30: 150 | EO30: 150 | EP30: 150 | EQ30: 150 | ER30: 200 | ES30: 200 | ET30: 200 | EU30: 200
G31: Actual
G32: Difference | BI32: =IF(ISBLANK(BI31),"",BI31-BI30) | BJ32: =IF(ISBLANK(BJ31),"",BJ31-BJ30) | BK32: =IF(ISBLANK(BK31),"",BK31-BK30) | BL32: =IF(ISBLANK(BL31),"",BL31-BL30) | BM32: =IF(ISBLANK(BM31),"",BM31-BM30) | BN32: =IF(ISBLANK(BN31),"",BN31-BN30) | BO32: =IF(ISBLANK(BO31),"",BO31-BO30) | BP32: =IF(ISBLANK(BP31),"",BP31-BP30) | ... EU32: =IF(ISBLANK(EU31),"",EU31-EU30)
G33: Cumulative Difference | BI33: =IFERROR(IF(ISBLANK(BI32),"",BI32+BH33),"") | BJ33: =IFERROR(IF(ISBLANK(BJ32),"",BJ32+BI33),"") | BK33: =IFERROR(IF(ISBLANK(BK32),"",BK32+BJ33),"") | BL33: =IFERROR(IF(ISBLANK(BL32),"",BL32+BK33),"") | BM33: =IFERROR(IF(ISBLANK(BM32),"",BM32+BL33),"") | BN33: =IFERROR(IF(ISBLANK(BN32),"",BN32+BM33),"") | BO33: =IFERROR(IF(ISBLANK(BO32),"",BO32+BN33),"") | BP33: =IFERROR(IF(ISBLANK(BP32),"",BP32+BO33),"") | ... EU33: =IFERROR(IF(ISBLANK(EU32),"",EU32+ET33),"")
A35: Enabling Earthwork's Task | AE35: Task 4.1 - Prelim Pad Prep | AF35: Task 4.1 - Prelim Pad Prep | AG35: Task 4.1 - Prelim Pad Prep | AW35: Task 4.2 - Complete Pad Prep | AX35: Task 4.2 - Complete Pad Prep | AY35: Task 4.2 - Complete Pad Prep | AZ35: Task 4.2 - Complete Pad Prep | BA35: Task 4.2 - Complete Pad Prep | BB35: Task 4.2 - Complete Pad Prep | BC35: Task 4.2 - Complete Pad Prep | BD35: Task 4.2 - Complete Pad Prep | BE35: Task 4.2 - Complete Pad Prep | BK35: Task 4.2 - Complete Pad Prep | BL35: Task 4.2 - Complete Pad Prep | BM35: Task 4.2 - Complete Pad Prep | BN35: Task 4.2 - Complete Pad Prep
A36: =IF((C36+2.5)>=B36,TRUE,FALSE) -> TRUE | B36: 117.5 | C36: =SUM(Y36:XFD36) -> 118 | E36: Earthworks | AE36: 2.5 | AF36: 2.5 | AG36: 2.5 | AW36: 8.5 | AX36: 8.5 | AY36: 8.5 | AZ36: 8.5 | BA36: 8.5 | BB36: 8.5 | BC36: 8.5 | BD36: 8.5 | BE36: 8.5 | BK36: 8.5 | BL36: 8.5 | BM36: 8.5 | BN36: 8.5
E37: HYD1 | G37: Drilling Phase | BS37: Bores | BT37: Bores | BU37: Bores | BV37: Bores | BW37: Bores | BX37: Bores | BY37: Bores | BZ37: Bores | CA37: Bores | CB37: Bores | CC37: Bores | CD37: Bores | CE37: Bores | CF37: Bores | CG37: Bores | CH37: Bores | CI37: Bores | CJ37: Bores | CK37: Bores | CL37: Bores | CM37: Bores | CN37: Bores | CO37: Bores | CP37: Bores | CQ37: Bores | CR37: Bores | CS37: Bores | CT37: Bores | CU37: Bores | CV37: Bores | CW37: Bores | CX37: Bores | CY37: Bores | CZ37: Bores | DA37: Bores | DB37: Bores | DC37: Bores | DD37: Bores | DE37: Bores
E38: Rig 18 | F38: Drilling | G38: Predicted | BS38: 22 | BT38: 22 | BU38: 22 | BV38: 22 | BW38: 22 | BX38: 22 | BY38: 22 | BZ38: 22 | CA38: 22 | CB38: 22 | CC38: 22 | CD38: 22 | CE38: 22 | CF38: 22 | CG38: 22 | CH38: 22 | CI38: 22 | CJ38: 22 | CK38: 22 | CL38: 22 | CM38: 22 | CN38: 22 | CO38: 22 | CP38: 22 | CQ38: 22 | CR38: 22 | CS38: 22 | CT38: 22 | CU38: 22 | CV38: 22 | CW38: 22 | CX38: 22 | CY38: 22 | CZ38: 22 | DA38: 22 | DB38: 22 | DC38: 22 | DD38: 22 | DE38: 22
G39: Actual | BS39: 78 | BT39: 36 | BU39: 6 | BV39: 90 | BW39: 30 | BX39: 125 | BY39: 96 | BZ39: 63 | CA39: 0 | CB39: 0 | CC39: 0 | CD39: 0 | CE39: 0 | CF39: 0 | CG39: 0 | CH39: 3 | CI39: 27 | CJ39: 70 | CK39: 24 | CL39: 46 | CM39: 34 | CN39: 74 | CO39: 28 | CP39: 30 | CQ39: 18
G40: Difference | BS40: =IF(ISBLANK(BS39),"",BS39-BS38) -> 56 | BT40: =IF(ISBLANK(BT39),"",BT39-BT38) -> 14 | BU40: =IF(ISBLANK(BU39),"",BU39-BU38) -> -16 | BV40: =IF(ISBLANK(BV39),"",BV39-BV38) -> 68 | BW40: =IF(ISBLANK(BW39),"",BW39-BW38) -> 8 | BX40: =IF(ISBLANK(BX39),"",BX39-BX38) -> 103 | BY40: =IF(ISBLANK(BY39),"",BY39-BY38) -> 74 | BZ40: =IF(ISBLANK(BZ39),"",BZ39-BZ38) -> 41 | ... DE40: =IF(ISBLANK(DE39),"",DE39-DE38)
G41: Cumulative Difference | BS41: =IFERROR(IF(ISBLANK(BS40),"",BS40+BR41),"") -> 56 | BT41: =IFERROR(IF(ISBLANK(BT40),"",BT40+BS41),"") -> 70 | BU41: =IFERROR(IF(ISBLANK(BU40),"",BU40+BT41),"") -> 54 | BV41: =IFERROR(IF(ISBLANK(BV40),"",BV40+BU41),"") -> 122 | BW41: =IFERROR(IF(ISBLANK(BW40),"",BW40+BV41),"") -> 130 | BX41: =IFERROR(IF(ISBLANK(BX40),"",BX40+BW41),"") -> 233 | BY41: =IFERROR(IF(ISBLANK(BY40),"",BY40+BX41),"") -> 307 | BZ41: =IFERROR(IF(ISBLANK(BZ40),"",BZ40+BY41),"") -> 348 | ... DE41: =IFERROR(IF(ISBLANK(DE40),"",DE40+DD41),"")
...

Sheet Pivot_Rig38
A9: RIG38
A10: Row Labels | B10: Sum of Completed Holes | C10: Sum of Total Length PQ | D10: Sum of Total Length HQ | E10: Sum of Charged Drilling Cost | F10: Sum of Active Hours total Cost | G10: Sum of Standby & Inactive Total Cost | H10: Sum of Tool Hire Cost | I10: Sum of Total Activity Hours Cost | J10: Sum of ***Insert Total Consumable Costs*** | K10: Sum of Total Costs
C11: 0 | D11: 0 | E11: 0 | F11: 0 | G11: 3780 | H11: 0 | I11: 3780 | K11: 3780
A12: DDRD | B12: 1 | C12: 0 | D12: 84.6 | E12: 13623 | F12: 6900 | G12: 45.625 | H12: 1500 | I12: 12750 | J12: 7504.06 | K12: 35767.06
A13: GT | B13: 7 | C13: 10.1 | D13: 333.9 | E13: 67505 | F13: 29440 | G13: 12871 | H13: 7425 | I13: 44650 | J13: 10934.64 | K13: 130514.64
A14: MET | B14: 9 | C14: 749 | D14: 2.3 | E14: 143015 | F14: 54280 | G14: 7471.5 | H14: 12200 | I14: 63910 | J14: 37761.28 | K14: 256886.28
A15: (blank) | C15: 0 | D15: 0 | E15: 0 | F15: 0 | G15: 0 | H15: 0 | I15: 0 | K15: 0
A16: Grand Total | B16: 17 | C16: 759.1 | D16: 420.8 | E16: 224143 | F16: 90620 | G16: 24168.125 | H16: 21125 | I16: 125090 | J16: 56199.98 | K16: 426947.98
A17: Row Labels | B17: Sum of Planned Holes | C17: Sum of Planned Metres
A18: A-Vein Resource Extension | B18: 47 | C18: 4185
A19: RD | B19: 47 | C19: 4185
A20: DD | B20: 5 | C20: 450
A21: RC | B21: 42 | C21: 3735
A22: DFS Met Sample collection (24 no. Holes, 2,045m) | B22: 24 | C22: 2045
A23: MET | B23: 24 | C23: 2045
A24: DD | B24: 24 | C24: 2045
A25: Dingo Vein Exploration | B25: 7 | C25: 630
A26: EXP | B26: 7 | C26: 630
A27: RC | B27: 7 | C27: 630
A28: Geotechnical drilling (12 no. HQ Holes, 1040m) | B28: 12 | C28: 1040
A29: GT | B29: 12 | C29: 1040
... A41: RC | B41: 10 | C41: 900
A42: (blank)
A43: Grand Total | B43: 307 | C43: 33601

Sheet DDH1 RIG 38_Data
A1: RIG 38 | G1: Rate | H1: 130 | I1: Hole 1 | K1: 175 | N1: 135 | O1: Hole 2 | Q1: 175 | T1: 135 | Z1: 175 | AA1: 155 | AB1: 420 | AE1: 460 | AF1: 460 | AH1: 360 | AI1: 360
E2: Hole 1 | F2: Hole 2 | I2: PQ3 | L2: HQ3 | O2: PQ3 | R2: HQ3 | Y2: Slow Pen rate Normalised | AK2: 0 | AL2: 0
A3: Hole Type | B3: Completion | C3: Date | D3: Shift | E3: Hole ID | F3: Hole ID2 | G3: Personel (incl driller) | H3: Accom Cost | I3: Depth From | J3: Depth To | K3: Length | L3: Depth From3 | M3: Depth To4 | N3: Length5 | O3: Depth From6 | P3: Depth To7 | Q3: Length8 | R3: Depth From9 | S3: Depth To10 | T3: Length11 | U3: Total Length PQ | V3: Total Length HQ | W3: Total Length | X3: Drilling Cost | Y3: Charged Drilling Cost | Z3: PQ Ori Tool | AA3: HQ Ori Tool | AB3: Gyro Tool | AC3: Tool ID | AD3: Tool Hire Cost | AE3: Drill Time | AF3: Active hours (Other than drilling) | AG3: Active Hours total Cost | AH3: Inactive Hours (Other than client standby) | AI3: Standby Total Hours | AJ3: Standby & Inactive Total Cost | AK3: Uncharged Hours | AL3: Maintenance | AM3: Total Daily Hours | AN3: Total Activity Hours Cost | AO3: ***Insert Total Consumable Costs*** | AP3: Total Consumables Cost (-accom) | AQ3: Total Costs | AR3: Plod Cost (Comparison) | AS3: Cummulative Cost | AT3: Month | AU3: Day | AV3: Shift Shorthand
A4: =IFERROR(IF(FIND("MET",E4),"MET",IF(FIND("GT",E4),"GT",)),"") | C4: =45843.21 -> 45843.21 | D4: DS 5am | H4: =IF(ISBLANK(G4),"",G4*$H$1) | K4: =IF(ISBLANK(I4),"",J4-I4) | N4: =IF(ISBLANK(L4),,M4-L4) -> 0 | Q4: =IF(ISBLANK(O4),,P4-O4) -> 0 | T4: =IF(ISBLANK(R4),,S4-R4) -> 0 | U4: =SUM(K4,Q4) -> 0 | V4: =SUM(N4,T4) -> 0 | W4: =IFERROR(K4+N4+Q4+T4,"") | X4: =IFERROR((K4*$K$1)+(N4*$N$1)+(Q4*$Q$1)+(T4*$T$1),"") | Y4: =IF(E4<>"",IF(X4<(AE4*$AE$1),(AE4*$AE$1),X4),"") | AA4: 1 | AB4: 1 | AE4: 0 | AF4: 0 | AG4: =Table3[[#This Row],[Active hours (Other than drilling)]]*$AF$1 -> 0 | AH4: 3.5 | AJ4: {=SUM(Table3[[#This Row],[Inactive Hours (Other than client standby)]:[Standby Total Hours]]*$AI$1)} -> 1260 | AK4: 8.5 | AM4: =IF(ISBLANK(AE4),"",SUM(AE4:AF4,AH4:AI4,AK4:AL4)) -> 12 | AN4: =(AF4*$AF$1)+(AH4*$AH$1)+(AI4*$AI$1) -> 1260 | AQ4: =SUM(Y4,AN4,AP4,H4)+AD4 -> 1260 | AS4: =SUM($AQ4:AQ$6) -> 3780 | AT4: =_xlfn.TEXTJOIN(,TRUE,"0",MONTH(C4)) -> 07 | AU4: =DAY(C4) -> 5 | AV4: =LEFT(D4,1) -> D
A5: =IFERROR(IF(FIND("MET",E5),"MET",IF(FIND("GT",E5),"GT",)),"") | C5: =45843 -> 45843 | D5: NS 5pm | H5: =IF(ISBLANK(G5),"",G5*$H$1) | K5: =IF(ISBLANK(I5),"",J5-I5) | N5: =IF(ISBLANK(L5),,M5-L5) -> 0 | Q5: =IF(ISBLANK(O5),,P5-O5) -> 0 | T5: =IF(ISBLANK(R5),,S5-R5) -> 0 | U5: =SUM(K5,Q5) -> 0 | V5: =SUM(N5,T5) -> 0 | W5: =IFERROR(K5+N5+Q5+T5,"") | X5: =IFERROR((K5*$K$1)+(N5*$N$1)+(Q5*$Q$1)+(T5*$T$1),"") | Y5: =IF(E5<>"",IF(X5<(AE5*$AE$1),(AE5*$AE$1),X5),"") | AE5: 0 | AF5: 0 | AG5: =Table3[[#This Row],[Active hours (Other than drilling)]]*$AF$1 -> 0 | AH5: 3.5 | AJ5: {=SUM(Table3[[#This Row],[Inactive Hours (Other than client standby)]:[Standby Total Hours]]*$AI$1)} -> 1260 | AK5: 7.5 | AM5: =IF(ISBLANK(AE5),"",SUM(AE5:AF5,AH5:AI5,AK5:AL5)) -> 11 | AN5: =(AF5*$AF$1)+(AH5*$AH$1)+(AI5*$AI$1) -> 1260 | AQ5: =SUM(Y5,AN5,AP5,H5)+AD5 -> 1260 | AS5: =SUM($AQ5:AQ$6) -> 2520 | AT5: =_xlfn.TEXTJOIN(,TRUE,"0",MONTH(C5)) -> 07 | AU5: =DAY(C5) -> 5 | AV5: =LEFT(D5,1) -> N
A6: =IFERROR(IF(FIND("MET",E6),"MET",IF(FIND("GT",E6),"GT",)),"") | C6: =45843.21+1 -> 45844.21 | D6: DS 5am | H6: =IF(ISBLANK(G6),"",G6*$H$1) | K6: =IF(ISBLANK(I6),"",J6-I6) | N6: =IF(ISBLANK(L6),,M6-L6) -> 0 | Q6: =IF(ISBLANK(O6),,P6-O6) -> 0 | T6: =IF(ISBLANK(R6),,S6-R6) -> 0 | U6: =SUM(K6,Q6) -> 0 | V6: =SUM(N6,T6) -> 0 | W6: =IFERROR(K6+N6+Q6+T6,"") | X6: =IFERROR((K6*$K$1)+(N6*$N$1)+(Q6*$Q$1)+(T6*$T$1),"") | Y6: =IF(E6<>"",IF(X6<(AE6*$AE$1),(AE6*$AE$1),X6),"") | AA6: 1 | AB6: 1 | AE6: 0 | AF6: 0 | AG6: =Table3[[#This Row],[Active hours (Other than drilling)]]*$AF$1 -> 0 | AH6: 3.5 | AJ6: {=SUM(Table3[[#This Row],[Inactive Hours (Other than client standby)]:[Standby Total Hours]]*$AI$1)} -> 1260 | AK6: 8.5 | AM6: =IF(ISBLANK(AE6),"",SUM(AE6:AF6,AH6:AI6,AK6:AL6)) -> 12 | AN6: =(AF6*$AF$1)+(AH6*$AH$1)+(AI6*$AI$1) -> 1260 | AQ6: =SUM(Y6,AN6,AP6,H6)+AD6 -> 1260 | AR6: 1260 | AS6: =SUM($AQ$6:AQ6) -> 1260 | AT6: =_xlfn.TEXTJOIN(,TRUE,"0",MONTH(C6)) -> 07 | AU6: =DAY(C6) -> 6 | AV6: =LEFT(D6,1) -> D
A7: =IFERROR(IF(FIND("MET",E7),"MET",IF(FIND("GT",E7),"GT",)),"") | C7: =45843.71+1 -> 45844.71 | D7: NS 5pm | H7: =IF(ISBLANK(G7),"",G7*$H$1) | K7: =IF(ISBLANK(I7),"",J7-I7) | N7: =IF(ISBLANK(L7),,M7-L7) -> 0 | Q7: =IF(ISBLANK(O7),,P7-O7) -> 0 | T7: =IF(ISBLANK(R7),,S7-R7) -> 0 | U7: =SUM(K7,Q7) -> 0 | V7: =SUM(N7,T7) -> 0 | W7: =IFERROR(K7+N7+Q7+T7,"") | X7: =IFERROR((K7*$K$1)+(N7*$N$1)+(Q7*$Q$1)+(T7*$T$1),"") | Y7: =IF(E7<>"",IF(X7<(AE7*$AE$1),(AE7*$AE$1),X7),"") | AG7: =Table3[[#This Row],[Active hours (Other than drilling)]]*$AF$1 -> 0 | AJ7: {=SUM(Table3[[#This Row],[Inactive Hours (Other than client standby)]:[Standby Total Hours]]*$AI$1)} -> 0 | AM7: =IF(ISBLANK(AE7),"",SUM(AE7:AF7,AH7:AI7,AK7:AL7)) | AN7: =(AF7*$AF$1)+(AH7*$AH$1)+(AI7*$AI$1) -> 0 | AQ7: =SUM(Y7,AN7,AP7,H7)+AD7 -> 0 | AR7: 0 | AS7: =SUM($AQ$6:AQ7) -> 1260 | AT7: =_xlfn.TEXTJOIN(,TRUE,"0",MONTH(C7)) -> 07 | AU7: =DAY(C7) -> 6 | AV7: =LEFT(D7,1) -> N
A8: MET | C8: =C6+1 -> 45845.21 | D8: DS 5am | E8: SF25_DMET023 | G8: 6 | H8: =IF(ISBLANK(G8),"",G8*$H$1) -> 780 | I8: 0 | J8: 0 | K8: =IF(ISBLANK(I8),"",J8-I8) -> 0 | N8: =IF(ISBLANK(L8),,M8-L8) -> 0 | Q8: =IF(ISBLANK(O8),,P8-O8) -> 0 | T8: =IF(ISBLANK(R8),,S8-R8) -> 0 | U8: =SUM(K8,Q8) -> 0 | V8: =SUM(N8,T8) -> 0 | W8: =IFERROR(K8+N8+Q8+T8,"") -> 0 | X8: =IFERROR((K8*$K$1)+(N8*$N$1)+(Q8*$Q$1)+(T8*$T$1),"") -> 0 | Y8: =IF(E8<>"",IF(X8<(AE8*$AE$1),(AE8*$AE$1),X8),"") -> 0 | AA8: 1 | AB8: 1 | AC8: 13170 | AD8: =SUMPRODUCT(Z8:AB8,$Z$1:$AB$1) -> 575 | AE8: 0 | AF8: 8.25 | AG8: =Table3[[#This Row],[Active hours (Other than drilling)]]*$AF$1 -> 3795 | AH8: 2 | AJ8: {=SUM(Table3[[#This Row],[Inactive Hours (Other than client standby)]:[Standby Total Hours]]*$AI$1)} -> 720 | AK8: 1.75 | AM8: =IF(ISBLANK(AE8),"",SUM(AE8:AF8,AH8:AI8,AK8:AL8)) -> 12 | AN8: =(AF8*$AF$1)+(AH8*$AH$1)+(AI8*$AI$1) -> 4515 | AO8: 1541 | AP8: 761 | AQ8: =SUM(Y8,AN8,AP8,H8)+AD8 -> 6631 | AR8: 6631 | AS8: =SUM($AQ$6:AQ8) -> 7891 | AT8: =_xlfn.TEXTJOIN(,TRUE,"0",MONTH(C8)) -> 07 | AU8: =DAY(C8) -> 7 | AV8: =LEFT(D8,1) -> D
C9: =C7+1 -> 45845.71 | D9: NS 5pm | H9: =IF(ISBLANK(G9),"",G9*$H$1) | K9: =IF(ISBLANK(I9),"",J9-I9) | N9: =IF(ISBLANK(L9),,M9-L9) -> 0 | Q9: =IF(ISBLANK(O9),,P9-O9) -> 0 | T9: =IF(ISBLANK(R9),,S9-R9) -> 0 | U9: =SUM(K9,Q9) -> 0 | V9: =SUM(N9,T9) -> 0 | W9: =IFERROR(K9+N9+Q9+T9,"") | X9: =IFERROR((K9*$K$1)+(N9*$N$1)+(Q9*$Q$1)+(T9*$T$1),"") | Y9: =IF(E9<>"",IF(X9<(AE9*$AE$1),(AE9*$AE$1),X9),"") | AD9: =SUMPRODUCT(Z9:AB9,$Z$1:$AB$1) -> 0 | AG9: =Table3[[#This Row],[Active hours (Other than drilling)]]*$AF$1 -> 0 | AJ9: {=SUM(Table3[[#This Row],[Inactive Hours (Other than client standby)]:[Standby Total Hours]]*$AI$1)} -> 0 | AM9: =IF(ISBLANK(AE9),"",SUM(AE9:AF9,AH9:AI9,AK9:AL9)) | AN9: =(AF9*$AF$1)+(AH9*$AH$1)+(AI9*$AI$1) -> 0 | AQ9: =SUM(Y9,AN9,AP9,H9)+AD9 -> 0 | AR9: 0 | AS9: =SUM($AQ$6:AQ9) -> 7891 | AT9: =_xlfn.TEXTJOIN(,TRUE,"0",MONTH(C9)) -> 07 | AU9: =DAY(C9) -> 7 | AV9: =LEFT(D9,1) -> N
A10: MET | C10: =C8+1 -> 45846.21 | D10: DS 5am | E10: SF25_DMET023 | G10: 3 | H10: =IF(ISBLANK(G10),"",G10*$H$1) -> 390 | I10: 0 | J10: 11 | K10: =IF(ISBLANK(I10),"",J10-I10) -> 11 | N10: =IF(ISBLANK(L10),,M10-L10) -> 0 | Q10: =IF(ISBLANK(O10),,P10-O10) -> 0 | T10: =IF(ISBLANK(R10),,S10-R10) -> 0 | U10: =SUM(K10,Q10) -> 11 | V10: =SUM(N10,T10) -> 0 | W10: =IFERROR(K10+N10+Q10+T10,"") -> 11 | X10: =IFERROR((K10*$K$1)+(N10*$N$1)+(Q10*$Q$1)+(T10*$T$1),"") -> 1925 | Y10: =IF(E10<>"",IF(X10<(AE10*$AE$1),(AE10*$AE$1),X10),"") -> 1955 | AA10: 1 | AB10: 1 | AC10: 13170 | AD10: =SUMPRODUCT(Z10:AB10,$Z$1:$AB$1) -> 575 | AE10: 4.25 | AF10: 7 | AG10: =Table3[[#This Row],[Active hours (Other than drilling)]]*$AF$1 -> 3220 | AH10: 0.75 | AJ10: {=SUM(Table3[[#This Row],[Inactive Hours (Other than client standby)]:[Standby Total Hours]]*$AI$1)} -> 270 | AM10: =IF(ISBLANK(AE10),"",SUM(AE10:AF10,AH10:AI10,AK10:AL10)) -> 12 | AN10: =(AF10*$AF$1)+(AH10*$AH$1)+(AI10*$AI$1) -> 3490 | AO10: 1076.34 | AP10: =1076.34-390 -> 686.34 | AQ10: =SUM(Y10,AN10,AP10,H10)+AD10 -> 7096.34 | AR10: 7096.34 | AS10: =SUM($AQ$6:AQ10) -> 14987.34 | AT10: =_xlfn.TEXTJOIN(,TRUE,"0",MONTH(C10)) -> 07 | AU10: =DAY(C10) -> 8 | AV10: =LEFT(D10,1) -> D
A11: MET | C11: =C9+1 -> 45846.71 | D11: NS 5pm | E11: SF25_DMET023 | G11: 3 | H11: =IF(ISBLANK(G11),"",G11*$H$1) -> 390 | I11: 11 | J11: 26.6 | K11: =IF(ISBLANK(I11),"",J11-I11) -> 15.6 | N11: =IF(ISBLANK(L11),,M11-L11) -> 0 | Q11: =IF(ISBLANK(O11),,P11-O11) -> 0 | T11: =IF(ISBLANK(R11),,S11-R11) -> 0 | U11: =SUM(K11,Q11) -> 15.6 | V11: =SUM(N11,T11) -> 0 | W11: =IFERROR(K11+N11+Q11+T11,"") -> 15.6 | X11: =IFERROR((K11*$K$1)+(N11*$N$1)+(Q11*$Q$1)+(T11*$T$1),"") -> 2730 | Y11: =IF(E11<>"",IF(X11<(AE11*$AE$1),(AE11*$AE$1),X11),"") -> 3335 | AD11: =SUMPRODUCT(Z11:AB11,$Z$1:$AB$1) -> 0 | AE11: 7.25 | AF11: 1.5 | AG11: =Table3[[#This Row],[Active hours (Other than drilling)]]*$AF$1 -> 690 | AH11: 0.25 | AJ11: {=SUM(Table3[[#This Row],[Inactive Hours (Other than client standby)]:[Standby Total Hours]]*$AI$1)} -> 90 | AK11: 3 | AM11: =IF(ISBLANK(AE11),"",SUM(AE11:AF11,AH11:AI11,AK11:AL11)) -> 12 | AN11: =(AF11*$AF$1)+(AH11*$AH$1)+(AI11*$AI$1) -> 780 | AO11: 507.93 | AP11: 117.93 | AQ11: =SUM(Y11,AN11,AP11,H11)+AD11 -> 4622.93 | AR11: 4622.93 | AS11: =SUM($AQ$6:AQ11) -> 19610.27 | AT11: =_xlfn.TEXTJOIN(,TRUE,"0",MONTH(C11)) -> 07 | AU11: =DAY(C11) -> 8 | AV11: =LEFT(D11,1) -> N
A12: MET | C12: =C10+1 -> 45847.21 | D12: DS 5am | E12: SF25_DMET023 | G12: 3 | H12: =IF(ISBLANK(G12),"",G12*$H$1) -> 390 | I12: 26.6 | J12: 33.7 | K12: =IF(ISBLANK(I12),"",J12-I12) -> 7.1 | N12: =IF(ISBLANK(L12),,M12-L12) -> 0 | Q12: =IF(ISBLANK(O12),,P12-O12) -> 0 | T12: =IF(ISBLANK(R12),,S12-R12) -> 0 | U12: =SUM(K12,Q12) -> 7.1 | V12: =SUM(N12,T12) -> 0 | W12: =IFERROR(K12+N12+Q12+T12,"") -> 7.1 | X12: =IFERROR((K12*$K$1)+(N12*$N$1)+(Q12*$Q$1)+(T12*$T$1),"") -> 1242.5 | Y12: =IF(E12<>"",IF(X12<(AE12*$AE$1),(AE12*$AE$1),X12),"") -> 1380 | AA12: 1 | AB12: 1 | AC12: 13170 | AD12: =SUMPRODUCT(Z12:AB12,$Z$1:$AB$1) -> 575 | AE12: 3 | AF12: 0.25 | AG12: =Table3[[#This Row],[Active hours (Other than drilling)]]*$AF$1 -> 115 | AH12: 0.25 | AJ12: {=SUM(Table3[[#This Row],[Inactive Hours (Other than client standby)]:[Standby Total Hours]]*$AI$1)} -> 90 | AK12: 8.5 | AM12: =IF(ISBLANK(AE12),"",SUM(AE12:AF12,AH12:AI12,AK12:AL12)) -> 12 | AN12: =(AF12*$AF$1)+(AH12*$AH$1)+(AI12*$AI$1) -> 205 | AO12: 390 | AP12: 0 | AQ12: =SUM(Y12,AN12,AP12,H12)+AD12 -> 2550 | AR12: 2550 | AS12: =SUM($AQ$6:AQ12) -> 22160.27 | AT12: =_xlfn.TEXTJOIN(,TRUE,"0",MONTH(C12)) -> 07 | AU12: =DAY(C12) -> 9 | AV12: =LEFT(D12,1) -> D
A13: MET | C13: =C11+1 -> 45847.71 | D13: NS 5pm | E13: SF25_DMET023 | G13: 3 | H13: =IF(ISBLANK(G13),"",G13*$H$1) -> 390 | I13: 33.7 | J13: 63.7 | K13: =IF(ISBLANK(I13),"",J13-I13) -> 30 | N13: =IF(ISBLANK(L13),,M13-L13) -> 0 | Q13: =IF(ISBLANK(O13),,P13-O13) -> 0 | T13: =IF(ISBLANK(R13),,S13-R13) -> 0 | U13: =SUM(K13,Q13) -> 30 | V13: =SUM(N13,T13) -> 0 | W13: =IFERROR(K13+N13+Q13+T13,"") -> 30 | X13: =IFERROR((K13*$K$1)+(N13*$N$1)+(Q13*$Q$1)+(T13*$T$1),"") -> 5250 | Y13: =IF(E13<>"",IF(X13<(AE13*$AE$1),(AE13*$AE$1),X13),"") -> 5250 | AD13: =SUMPRODUCT(Z13:AB13,$Z$1:$AB$1) -> 0 | AE13: 10.75 | AF13: 0.75 | AG13: =Table3[[#This Row],[Active hours (Other than drilling)]]*$AF$1 -> 345 | AH13: 0.5 | AJ13: {=SUM(Table3[[#This Row],[Inactive Hours (Other than client standby)]:[Standby Total Hours]]*$AI$1)} -> 180 | AM13: =IF(ISBLANK(AE13),"",SUM(AE13:AF13,AH13:AI13,AK13:AL13)) -> 12 | AN13: =(AF13*$AF$1)+(AH13*$AH$1)+(AI13*$AI$1) -> 525 | AO13: 507.93 | AP13: 117.93 | AQ13: =SUM(Y13,AN13,AP13,H13)+AD13 -> 6282.93 | AR13: 6282.93 | AS13: =SUM($AQ$6:AQ13) -> 28443.2 | AT13: =_xlfn.TEXTJOIN(,TRUE,"0",MONTH(C13)) -> 07 | AU13: =DAY(C13) -> 9 | AV13: =LEFT(D13,1) -> N
A14: MET | C14: =C12+1 -> 45848.21 | D14: DS 5am | E14: SF25_DMET023 | G14: 3 | H14: =IF(ISBLANK(G14),"",G14*$H$1) -> 390 | I14: 63.7 | J14: 84.1 | K14: =IF(ISBLANK(I14),"",J14-I14) -> 20.4 | N14: =IF(ISBLANK(L14),,M14-L14) -> 0 | Q14: =IF(ISBLANK(O14),,P14-O14) -> 0 | T14: =IF(ISBLANK(R14),,S14-R14) -> 0 | U14: =SUM(K14,Q14) -> 20.4 | V14: =SUM(N14,T14) -> 0 | W14: =IFERROR(K14+N14+Q14+T14,"") -> 20.4 | X14: =IFERROR((K14*$K$1)+(N14*$N$1)+(Q14*$Q$1)+(T14*$T$1),"") -> 3570 | Y14: =IF(E14<>"",IF(X14<(AE14*$AE$1),(AE14*$AE$1),X14),"") -> 5060 | AA14: 1 | AB14: 1 | AC14: 13170 | AD14: =SUMPRODUCT(Z14:AB14,$Z$1:$AB$1) -> 575 | AE14: 11 | AF14: 0.5 | AG14: =Table3[[#This Row],[Active hours (Other than drilling)]]*$AF$1 -> 230 | AH14: 0.5 | AJ14: {=SUM(Table3[[#This Row],[Inactive Hours (Other than client standby)]:[Standby Total Hours]]*$AI$1)} -> 180 | AM14: =IF(ISBLANK(AE14),"",SUM(AE14:AF14,AH14:AI14,AK14:AL14)) -> 12 | AN14: =(AF14*$AF$1)+(AH14*$AH$1)+(AI14*$AI$1) -> 410 | AO14: 817.99 | AP14: =817.99-390 -> 427.99 | AQ14: =SUM(Y14,AN14,AP14,H14)+AD14 -> 6862.99 | AR14: 6862.99 | AS14: =SUM($AQ$6:AQ14) -> 35306.19 | AT14: =_xlfn.TEXTJOIN(,TRUE,"0",MONTH(C14)) -> 07 | AU14: =DAY(C14) -> 10 | AV14: =LEFT(D14,1) -> D
A15: MET | C15: =C13+1 -> 45848.71 | D15: NS 5pm | E15: SF25_DMET023 | G15: 3 | H15: =IF(ISBLANK(G15),"",G15*$H$1) -> 390 | I15: 84.1 | J15: 99.7 | K15: =IF(ISBLANK(I15),"",J15-I15) -> 15.6 | N15: =IF(ISBLANK(L15),,M15-L15) -> 0 | Q15: =IF(ISBLANK(O15),,P15-O15) -> 0 | T15: =IF(ISBLANK(R15),,S15-R15) -> 0 | U15: =SUM(K15,Q15) -> 15.6 | V15: =SUM(N15,T15) -> 0 | W15: =IFERROR(K15+N15+Q15+T15,"") -> 15.6 | X15: =IFERROR((K15*$K$1)+(N15*$N$1)+(Q15*$Q$1)+(T15*$T$1),"") -> 2730 | Y15: =IF(E15<>"",IF(X15<(AE15*$AE$1),(AE15*$AE$1),X15),"") -> 3105 | AD15: =SUMPRODUCT(Z15:AB15,$Z$1:$AB$1) -> 0 | AE15: 6.75 | AF15: 4.75 | AG15: =Table3[[#This Row],[Active hours (Other than drilling)]]*$AF$1 -> 2185 | AH15: 0.5 | AJ15: {=SUM(Table3[[#This Row],[Inactive Hours (Other than client standby)]:[Standby Total Hours]]*$AI$1)} -> 180 | AM15: =IF(ISBLANK(AE15),"",SUM(AE15:AF15,AH15:AI15,AK15:AL15)) -> 12 | AN15: =(AF15*$AF$1)+(AH15*$AH$1)+(AI15*$AI$1) -> 2365 | AO15: 1166.68 | AP15: =1166.68-390 -> 776.68 | AQ15: =SUM(Y15,AN15,AP15,H15)+AD15 -> 6636.68 | AR15: 6636.68 | AS15: =SUM($AQ$6:AQ15) -> 41942.87 | AT15: =_xlfn.TEXTJOIN(,TRUE,"0",MONTH(C15)) -> 07 | AU15: =DAY(C15) -> 10 | AV15: =LEFT(D15,1) -> N
A16: MET | B16: 1 | C16: =C14+1 -> 45849.21 | D16: DS 5am | E16: SF25_DMET023 | G16: 3 | H16: =IF(ISBLANK(G16),"",G16*$H$1) -> 390 | I16: 99.7 | J16: 118.7 | K16: =IF(ISBLANK(I16),"",J16-I16) -> 19 | N16: =IF(ISBLANK(L16),,M16-L16) -> 0 | Q16: =IF(ISBLANK(O16),,P16-O16) -> 0 | T16: =IF(ISBLANK(R16),,S16-R16) -> 0 | U16: =SUM(K16,Q16) -> 19 | V16: =SUM(N16,T16) -> 0 | W16: =IFERROR(K16+N16+Q16+T16,"") -> 19 | X16: =IFERROR((K16*$K$1)+(N16*$N$1)+(Q16*$Q$1)+(T16*$T$1),"") -> 3325 | Y16: =IF(E16<>"",IF(X16<(AE16*$AE$1),(AE16*$AE$1),X16),"") -> 3910 | AA16: 1 | AB16: 1 | AC16: 13170 | AD16: =SUMPRODUCT(Z16:AB16,$Z$1:$AB$1) -> 575 | AE16: 8.5 | AF16: 3 | AG16: =Table3[[#This Row],[Active hours (Other than drilling)]]*$AF$1 -> 1380 | AH16: 0.5 | AJ16: {=SUM(Table3[[#This Row],[Inactive Hours (Other than client standby)]:[Standby Total Hours]]*$AI$1)} -> 180 | AM16: =IF(ISBLANK(AE16),"",SUM(AE16:AF16,AH16:AI16,AK16:AL16)) -> 12 | AN16: =(AF16*$AF$1)+(AH16*$AH$1)+(AI16*$AI$1) -> 1560 | AO16: 390 | AQ16: =SUM(Y16,AN16,AP16,H16)+AD16 -> 6435 | AR16: 6435 | AS16: =SUM($AQ$6:AQ16) -> 48377.87 | AT16: =_xlfn.TEXTJOIN(,TRUE,"0",MONTH(C16)) -> 07 | AU16: =DAY(C16) -> 11 | AV16: =LEFT(D16,1) -> D
A17: MET | C17: =C15+1 -> 45849.71 | D17: NS 5pm | E17: SF25_DMET022 | G17: 3 | H17: =IF(ISBLANK(G17),"",G17*$H$1) -> 390 | I17: 0 | J17: 16.5 | K17: =IF(ISBLANK(I17),"",J17-I17) -> 16.5 | N17: =IF(ISBLANK(L17),,M17-L17) -> 0 | Q17: =IF(ISBLANK(O17),,P17-O17) -> 0 | T17: =IF(ISBLANK(R17),,S17-R17) -> 0 | U17: =SUM(K17,Q17) -> 16.5 | V17: =SUM(N17,T17) -> 0 | W17: =IFERROR(K17+N17+Q17+T17,"") -> 16.5 | X17: =IFERROR((K17*$K$1)+(N17*$N$1)+(Q17*$Q$1)+(T17*$T$1),"") -> 2887.5 | Y17: =IF(E17<>"",IF(X17<(AE17*$AE$1),(AE17*$AE$1),X17),"") -> 3335 | AD17: =SUMPRODUCT(Z17:AB17,$Z$1:$AB$1) -> 0 | AE17: 7.25 | AF17: 4.25 | AG17: =Table3[[#This Row],[Active hours (Other than drilling)]]*$AF$1 -> 1955 | AH17: 0.5 | AJ17: {=SUM(Table3[[#This Row],[Inactive Hours (Other than client standby)]:[Standby Total Hours]]*$AI$1)} -> 180 | AM17: =IF(ISBLANK(AE17),"",SUM(AE17:AF17,AH17:AI17,AK17:AL17)) -> 12 | AN17: =(AF17*$AF$1)+(AH17*$AH$1)+(AI17*$AI$1) -> 2135 | AO17: 786.12 | AP17: =786.12-390 -> 396.12 | AQ17: =SUM(Y17,AN17,AP17,H17)+AD17 -> 6256.12 | AR17: 6256.12 | AS17: =SUM($AQ$6:AQ17) -> 54633.99 | AT17: =_xlfn.TEXTJOIN(,TRUE,"0",MONTH(C17)) -> 07 | AU17: =DAY(C17) -> 11 | AV17: =LEFT(D17,1) -> N
A18: MET | C18: =C16+1 -> 45850.21 | D18: DS 5am | E18: SF25_DMET022 | G18: 3 | H18: =IF(ISBLANK(G18),"",G18*$H$1) -> 390 | I18: 16.5 | J18: 39.4 | K18: =IF(ISBLANK(I18),"",J18-I18) -> 22.9 | N18: =IF(ISBLANK(L18),,M18-L18) -> 0 | Q18: =IF(ISBLANK(O18),,P18-O18) -> 0 | T18: =IF(ISBLANK(R18),,S18-R18) -> 0 | U18: =SUM(K18,Q18) -> 22.9 | V18: =SUM(N18,T18) -> 0 | W18: =IFERROR(K18+N18+Q18+T18,"") -> 22.9 | X18: =IFERROR((K18*$K$1)+(N18*$N$1)+(Q18*$Q$1)+(T18*$T$1),"") -> 4007.5 | Y18: =IF(E18<>"",IF(X18<(AE18*$AE$1),(AE18*$AE$1),X18),"") -> 4945 | AA18: 1 | AB18: 1 | AC18: 13170 | AD18: =SUMPRODUCT(Z18:AB18,$Z$1:$AB$1) -> 575 | AE18: 10.75 | AF18: 0.25 | AG18: =Table3[[#This Row],[Active hours (Other than drilling)]]*$AF$1 -> 115 | AH18: 0.5 | AJ18: {=SUM(Table3[[#This Row],[Inactive Hours (Other than client standby)]:[Standby Total Hours]]*$AI$1)} -> 180 | AK18: 0.5 | AM18: =IF(ISBLANK(AE18),"",SUM(AE18:AF18,AH18:AI18,AK18:AL18)) -> 12 | AN18: =(AF18*$AF$1)+(AH18*$AH$1)+(AI18*$AI$1) -> 295 | AO18: 541.79 | AP18: 151.79 | AQ18: =SUM(Y18,AN18,AP18,H18)+AD18 -> 6356.79 | AR18: 6356.79 | AS18: =SUM($AQ$6:AQ18) -> 60990.78 | AT18: =_xlfn.TEXTJOIN(,TRUE,"0",MONTH(C18)) -> 07 | AU18: =DAY(C18) -> 12 | AV18: =LEFT(D18,1) -> D
A19: MET | C19: =C17+1 -> 45850.71 | D19: NS 5pm | E19: SF25_DMET022 | G19: 3 | H19: =IF(ISBLANK(G19),"",G19*$H$1) -> 390 | I19: 39.4 | J19: 60.6 | K19: =IF(ISBLANK(I19),"",J19-I19) -> 21.2 | N19: =IF(ISBLANK(L19),,M19-L19) -> 0 | Q19: =IF(ISBLANK(O19),,P19-O19) -> 0 | T19: =IF(ISBLANK(R19),,S19-R19) -> 0 | U19: =SUM(K19,Q19) -> 21.2 | V19: =SUM(N19,T19) -> 0 | W19: =IFERROR(K19+N19+Q19+T19,"") -> 21.2 | X19: =IFERROR((K19*$K$1)+(N19*$N$1)+(Q19*$Q$1)+(T19*$T$1),"") -> 3710 | Y19: =IF(E19<>"",IF(X19<(AE19*$AE$1),(AE19*$AE$1),X19),"") -> 3910 | AD19: =SUMPRODUCT(Z19:AB19,$Z$1:$AB$1) -> 0 | AE19: 8.5 | AF19: 2.5 | AG19: =Table3[[#This Row],[Active hours (Other than drilling)]]*$AF$1 -> 1150 | AH19: 0.5 | AJ19: {=SUM(Table3[[#This Row],[Inactive Hours (Other than client standby)]:[Standby Total Hours]]*$AI$1)} -> 180 | AK19: 0.5 | AM19: =IF(ISBLANK(AE19),"",SUM(AE19:AF19,AH19:AI19,AK19:AL19)) -> 12 | AN19: =(AF19*$AF$1)+(AH19*$AH$1)+(AI19*$AI$1) -> 1330 | AO19: 507.93 | AP19: 117.93 | AQ19: =SUM(Y19,AN19,AP19,H19)+AD19 -> 5747.93 | AR19: 5747.93 | AS19: =SUM($AQ$6:AQ19) -> 66738.71 | AT19: =_xlfn.TEXTJOIN(,TRUE,"0",MONTH(C19)) -> 07 | AU19: =DAY(C19) -> 12 | AV19: =LEFT(D19,1) -> N
A20: MET | C20: =C18+1 -> 45851.21 | D20: DS 5am | E20: SF25_DMET022 | G20: 3 | H20: =IF(ISBLANK(G20),"",G20*$H$1) -> 390 | I20: 60.6 | J20: 73.8 | K20: =IF(ISBLANK(I20),"",J20-I20) -> 13.2 | N20: =IF(ISBLANK(L20),,M20-L20) -> 0 | Q20: =IF(ISBLANK(O20),,P20-O20) -> 0 | T20: =IF(ISBLANK(R20),,S20-R20) -> 0 | U20: =SUM(K20,Q20) -> 13.2 | V20: =SUM(N20,T20) -> 0 | W20: =IFERROR(K20+N20+Q20+T20,"") -> 13.2 | X20: =IFERROR((K20*$K$1)+(N20*$N$1)+(Q20*$Q$1)+(T20*$T$1),"") -> 2310 | Y20: =IF(E20<>"",IF(X20<(AE20*$AE$1),(AE20*$AE$1),X20),"") -> 4025 | AA20: 1 | AB20: 1 | AC20: 13170 | AD20: =SUMPRODUCT(Z20:AB20,$Z$1:$AB$1) -> 575 | AE20: 8.75 | AF20: 2.75 | AG20: =Table3[[#This Row],[Active hours (Other than drilling)]]*$AF$1 -> 1265 | AH20: 0.5 | AJ20: {=SUM(Table3[[#This Row],[Inactive Hours (Other than client standby)]:[Standby Total Hours]]*$AI$1)} -> 180 | AM20: =IF(ISBLANK(AE20),"",SUM(AE20:AF20,AH20:AI20,AK20:AL20)) -> 12 | AN20: =(AF20*$AF$1)+(AH20*$AH$1)+(AI20*$AI$1) -> 1445 | AO20: 443.23 | AP20: 53.23 | AQ20: =SUM(Y20,AN20,AP20,H20)+AD20 -> 6488.23 | AR20: 6488.23 | AS20: =SUM($AQ$6:AQ20) -> 73226.94 | AT20: =_xlfn.TEXTJOIN(,TRUE,"0",MONTH(C20)) -> 07 | AU20: =DAY(C20) -> 13 | AV20: =LEFT(D20,1) -> D
A21: MET | C21: =C19+1 -> 45851.71 | D21: NS 5pm | E21: SF25_DMET022 | G21: 3 | H21: =IF(ISBLANK(G21),"",G21*$H$1) -> 390 | I21: 73.8 | J21: 101.1 | K21: =IF(ISBLANK(I21),"",J21-I21) -> 27.3 | N21: =IF(ISBLANK(L21),,M21-L21) -> 0 | Q21: =IF(ISBLANK(O21),,P21-O21) -> 0 | T21: =IF(ISBLANK(R21),,S21-R21) -> 0 | U21: =SUM(K21,Q21) -> 27.3 | V21: =SUM(N21,T21) -> 0 | W21: =IFERROR(K21+N21+Q21+T21,"") -> 27.3 | X21: =IFERROR((K21*$K$1)+(N21*$N$1)+(Q21*$Q$1)+(T21*$T$1),"") -> 4777.5 | Y21: =IF(E21<>"",IF(X21<(AE21*$AE$1),(AE21*$AE$1),X21),"") -> 5060 | AD21: =SUMPRODUCT(Z21:AB21,$Z$1:$AB$1) -> 0 | AE21: 11 | AF21: 0.5 | AG21: =Table3[[#This Row],[Active hours (Other than drilling)]]*$AF$1 -> 230 | AH21: 0.5 | AJ21: {=SUM(Table3[[#This Row],[Inactive Hours (Other than client standby)]:[Standby Total Hours]]*$AI$1)} -> 180 | AM21: =IF(ISBLANK(AE21),"",SUM(AE21:AF21,AH21:AI21,AK21:AL21)) -> 12 | AN21: =(AF21*$AF$1)+(AH21*$AH$1)+(AI21*$AI$1) -> 410 | AO21: 507.93 | AP21: 117.93 | AQ21: =SUM(Y21,AN21,AP21,H21)+AD21 -> 5977.93 | AR21: 5977.93 | AS21: =SUM($AQ$6:AQ21) -> 79204.87 | AT21: =_xlfn.TEXTJOIN(,TRUE,"0",MONTH(C21)) -> 07 | AU21: =DAY(C21) -> 13 | AV21: =LEFT(D21,1) -> N
A22: MET | B22: 1 | C22: =C20+1 -> 45852.21 | D22: DS 5am | E22: SF25_DMET022 | G22: 3 | H22: =IF(ISBLANK(G22),"",G22*$H$1) -> 390 | I22: 101.1 | J22: 120.7 | K22: =IF(ISBLANK(I22),"",J22-I22) -> 19.6 | N22: =IF(ISBLANK(L22),,M22-L22) -> 0 | Q22: =IF(ISBLANK(O22),,P22-O22) -> 0 | T22: =IF(ISBLANK(R22),,S22-R22) -> 0 | U22: =SUM(K22,Q22) -> 19.6 | V22: =SUM(N22,T22) -> 0 | W22: =IFERROR(K22+N22+Q22+T22,"") -> 19.6 | X22: =IFERROR((K22*$K$1)+(N22*$N$1)+(Q22*$Q$1)+(T22*$T$1),"") -> 3430 | Y22: =IF(E22<>"",IF(X22<(AE22*$AE$1),(AE22*$AE$1),X22),"") -> 3680 | AA22: 1 | AB22: 1 | AC22: 13170 | AD22: =SUMPRODUCT(Z22:AB22,$Z$1:$AB$1) -> 575 | AE22: 8 | AF22: 3.5 | AG22: =Table3[[#This Row],[Active hours (Other than drilling)]]*$AF$1 -> 1610 | AH22: 0.5 | AJ22: {=SUM(Table3[[#This Row],[Inactive Hours (Other than client standby)]:[Standby Total Hours]]*$AI$1)} -> 180 | AM22: =IF(ISBLANK(AE22),"",SUM(AE22:AF22,AH22:AI22,AK22:AL22)) -> 12 | AN22: =(AF22*$AF$1)+(AH22*$AH$1)+(AI22*$AI$1) -> 1790 | AO22: 390 | AQ22: =SUM(Y22,AN22,AP22,H22)+AD22 -> 6435 | AR22: 6435 | AS22: =SUM($AQ$6:AQ22) -> 85639.87 | AT22: =_xlfn.TEXTJOIN(,TRUE,"0",MONTH(C22)) -> 07 | AU22: =DAY(C22) -> 14 | AV22: =LEFT(D22,1) -> D
A23: MET | C23: =C21+1 -> 45852.71 | D23: NS 5pm | E23: SF25_DMET021 | G23: 3 | H23: =IF(ISBLANK(G23),"",G23*$H$1) -> 390 | I23: 0 | J23: 20.5 | K23: =IF(ISBLANK(I23),"",J23-I23) -> 20.5 | N23: =IF(ISBLANK(L23),,M23-L23) -> 0 | Q23: =IF(ISBLANK(O23),,P23-O23) -> 0 | T23: =IF(ISBLANK(R23),,S23-R23) -> 0 | U23: =SUM(K23,Q23) -> 20.5 | V23: =SUM(N23,T23) -> 0 | W23: =IFERROR(K23+N23+Q23+T23,"") -> 20.5 | X23: =IFERROR((K23*$K$1)+(N23*$N$1)+(Q23*$Q$1)+(T23*$T$1),"") -> 3587.5 | Y23: =IF(E23<>"",IF(X23<(AE23*$AE$1),(AE23*$AE$1),X23),"") -> 3795 | AD23: =SUMPRODUCT(Z23:AB23,$Z$1:$AB$1) -> 0 | AE23: 8.25 | AF23: 3.25 | AG23: =Table3[[#This Row],[Active hours (Other than drilling)]]*$AF$1 -> 1495 | AH23: 0.5 | AJ23: {=SUM(Table3[[#This Row],[Inactive Hours (Other than client standby)]:[Standby Total Hours]]*$AI$1)} -> 180 | AM23: =IF(ISBLANK(AE23),"",SUM(AE23:AF23,AH23:AI23,AK23:AL23)) -> 12 | AN23: =(AF23*$AF$1)+(AH23*$AH$1)+(AI23*$AI$1) -> 1675 | AO23: 625.86 | AP23: 235.86 | AQ23: =SUM(Y23,AN23,AP23,H23)+AD23 -> 6095.86 | AR23: 6095.86 | AS23: =SUM($AQ$6:AQ23) -> 91735.73 | AT23: =_xlfn.TEXTJOIN(,TRUE,"0",MONTH(C23)) -> 07 | AU23: =DAY(C23) -> 14 | AV23: =LEFT(D23,1) -> N
A24: MET | C24: =C22+1 -> 45853.21 | D24: DS 5am | E24: SF25_DMET021 | G24: 3 | H24: =IF(ISBLANK(G24),"",G24*$H$1) -> 390 | I24: 20.5 | J24: 50.5 | K24: =IF(ISBLANK(I24),"",J24-I24) -> 30 | N24: =IF(ISBLANK(L24),,M24-L24) -> 0 | Q24: =IF(ISBLANK(O24),,P24-O24) -> 0 | T24: =IF(ISBLANK(R24),,S24-R24) -> 0 | U24: =SUM(K24,Q24) -> 30 | V24: =SUM(N24,T24) -> 0 | W24: =IFERROR(K24+N24+Q24+T24,"") -> 30 | X24: =IFERROR((K24*$K$1)+(N24*$N$1)+(Q24*$Q$1)+(T24*$T$1),"") -> 5250 | Y24: =IF(E24<>"",IF(X24<(AE24*$AE$1),(AE24*$AE$1),X24),"") -> 5250 | AA24: 1 | AB24: 1 | AC24: 13170 | AD24: =SUMPRODUCT(Z24:AB24,$Z$1:$AB$1) -> 575 | AE24: 10.5 | AF24: 1 | AG24: =Table3[[#This Row],[Active hours (Other than drilling)]]*$AF$1 -> 460 | AH24: 0.5 | AJ24: {=SUM(Table3[[#This Row],[Inactive Hours (Other than client standby)]:[Standby Total Hours]]*$AI$1)} -> 180 | AM24: =IF(ISBLANK(AE24),"",SUM(AE24:AF24,AH24:AI24,AK24:AL24)) -> 12 | AN24: =(AF24*$AF$1)+(AH24*$AH$1)+(AI24*$AI$1) -> 640 | AO24: 1269.56 | AP24: 879.56 | AQ24: =SUM(Y24,AN24,AP24,H24)+AD24 -> 7734.56 | AR24: 7734.56 | AS24: =SUM($AQ$6:AQ24) -> 99470.29 | AT24: =_xlfn.TEXTJOIN(,TRUE,"0",MONTH(C24)) -> 07 | AU24: =DAY(C24) -> 15 | AV24: =LEFT(D24,1) -> D
A25: MET | C25: =C23+1 -> 45853.71 | D25: NS 5pm | E25: SF25_DMET021 | G25: 3 | H25: =IF(ISBLANK(G25),"",G25*$H$1) -> 390 | I25: 50.5 | J25: 80.6 | K25: =IF(ISBLANK(I25),"",J25-I25) -> 30.1 | N25: =IF(ISBLANK(L25),,M25-L25) -> 0 | Q25: =IF(ISBLANK(O25),,P25-O25) -> 0 | T25: =IF(ISBLANK(R25),,S25-R25) -> 0 | U25: =SUM(K25,Q25) -> 30.1 | V25: =SUM(N25,T25) -> 0 | W25: =IFERROR(K25+N25+Q25+T25,"") -> 30.1 | X25: =IFERROR((K25*$K$1)+(N25*$N$1)+(Q25*$Q$1)+(T25*$T$1),"") -> 5267.5 | Y25: =IF(E25<>"",IF(X25<(AE25*$AE$1),(AE25*$AE$1),X25),"") -> 5267.5 | AD25: =SUMPRODUCT(Z25:AB25,$Z$1:$AB$1) -> 0 | AE25: 10.25 | AF25: 1.25 | AG25: =Table3[[#This Row],[Active hours (Other than drilling)]]*$AF$1 -> 575 | AH25: 0.5 | AJ25: {=SUM(Table3[[#This Row],[Inactive Hours (Other than client standby)]:[Standby Total Hours]]*$AI$1)} -> 180 | AM25: =IF(ISBLANK(AE25),"",SUM(AE25:AF25,AH25:AI25,AK25:AL25)) -> 12 | AN25: =(AF25*$AF$1)+(AH25*$AH$1)+(AI25*$AI$1) -> 755 | AO25: 626.49 | AP25: 236.49 | AQ25: =SUM(Y25,AN25,AP25,H25)+AD25 -> 6648.99 | AR25: 6648.99 | AS25: =SUM($AQ$6:AQ25) -> 106119.28 | AT25: =_xlfn.TEXTJOIN(,TRUE,"0",MONTH(C25)) -> 07 | AU25: =DAY(C25) -> 15 | AV25: =LEFT(D25,1) -> N
